Workbook

Sheet Anleitung

Sheet Gliederradiator
A1: INPUT
A2: Bauhöhe (cm) | B2: 500 | E2: Obligatorische Werte
A3: Bautiefe (cm) | B3: 136 | E3: Ergänzende Werte: Sie ermöglichen es, die Anzahl der Glieder und Säulen zu validieren, falls nur die Abmessungen des Heizkörpers als Eingabefelder verwendet werden sollen. Können wir diese mit den folgenden Formeln umgerechnet werden.
A4: Länge (cm) | B4: 1170
A5: Anzahl Glieder | B5: 26 | C5: =IF(AND((0.85*B4/45)<B5,B5<(1.15*B4/45)),TRUE,"Anzahl der Glieder und Länge des Heizkörpers sind nicht kompatibel mit Berechnungsmodell") -> TRUE | E5: =ROUND(B4/45,0) -> 26
A6: Anzahl Säule | B6: 4 | C6: =IF(AND(B3<=70,B6=2),TRUE,IF(AND(70<B3,B3<=110,B6=3),TRUE,IF(AND(110<B3,B3<=150,B6=4),TRUE,IF(AND(150<B3,B3<=200,B6=5),TRUE,IF(AND(200<B3,B3<=250,B6=6),TRUE,"Die Anzahl von Säulen ist nicht mit der Radiatortiefe konsistent"))))) -> TRUE | E6: =IF(B3<=70,2,IF(AND(B3>70,B3<=110),3,IF(AND(B3>110,B3<=150),4,IF(AND(B3>150,B3<=200),5,IF(AND(B3>200,B3<=250),6))))) -> 4
A8: Vorlauftemperatur (°C) | B8: 55
A9: Rücklauftemperatur (°C) | B9: 45
A10: Raumlufttemperatur (°C) | B10: 22
A12: OUTPUT
A13: Leistung pro Glieder EN 442 | B13: =IF(B6=2,0.0701*B2+3.1231,IF(B6=3,0.0911*B2+7.6769,IF(B6=4,0.1145*B2+11.758,IF(B6=5,0.137*B2+16.647,IF(B6=6,0.1609*B2+20.129))))) -> 69.008
A14: Projektspezifische Leitung pro Glieder | B14: =B13*(((B8-B9)/(LN((B8-B10)/(B9-B10)))/'Exponent alle'!$N$28)^(IF(B6=2,-0.00000002*B2^2+0.00008*B2 + 1.2298,IF(B6=3,-0.00000001*B2^2+0.00006*B2 + 1.2636,IF(B6=4,-0.00000002*B2^2+0.00008*B2 + 1.2608,IF(B6=5,-0.00000002*B2^2+0.00007*B2 + 1.2826,IF(B6=6, -0.00000002*B2^2+0.00006*B2 + 1.2931))))))) -> 32.241817
A15: THGE pro Glieder | B15: =IF(B6=2,0.0016*B2+0.0569,IF(B6=3,0.0024*B2+0.0988,IF(B6=4,0.0032*B2+0.1482,IF(B6=5,0.004*B2+0.1919,IF(B6=6,0.0048*B2+0.2597))))) -> 1.7482
A17: Leistung EN 442 | B17: =B5*B13 -> 1794.208
A18: Projektspezifische Leitung | B18: =B5*B14 -> 838.28725
A19: THGE | B19: =IF(B5="",ROUND((B4-2.6)/4.6,0)*B15,IF(((0.75*B5)>(B4-2.6)/4.6)>(1.25*B5),B5*B15,"Anzahl der Glieder und Länge des Heizkörpers sind nicht kompatibel mit Berechnungsmodell")) -> 45.4532

Sheet Plattenradiator
A1: Bauhöhe (cm) | B1: 500
A2: Länge (cm) | B2: 1000
A3: Bautiefe (cm) | B3: 62
A4: Model | B4: 11
A6: Vorlauftemperatur (°C) | B6: 55
A7: Rücklauftemperatur (°C) | B7: 45
A8: Raumlufttemperatur (°C) | B8: 22
A10: Leistung EN 442 | B10: =IF(B4=11,'Basis Radiator'!Y52,IF(B4=20,'Basis Radiator'!AQ52,IF(B4=21,'Basis Radiator'!AV52,IF(B4=22,'Basis Radiator'!BV52,'Basis Radiator'!CN52)))) -> 7800
A11: Projektspezifische Leistung | B11: =B10*(((B6-B7)/(LN((B6-B8)/(B7-B8)))/'Basis Radiator'!B62)^'Basis Radiator'!A53) -> 3699.9401
A12: THGE pro Glieder | B12: =IF(B4=11,'Basis Radiator'!Y54,IF(B4=20,'Basis Radiator'!AQ54,IF(B4=21,'Basis Radiator'!AV54,IF(B4=22,'Basis Radiator'!BV54,'Basis Radiator'!CN52)))) -> 0

Sheet DIN 4720 4722
A3: DIN 4722 | Z3: DIN 4722
A4: Stahlradiatoren | B4: 50 mm/Glieder | Z4: Stahlradiatoren | AA4: 60 mm/Glieder
A6: Nabenabstand h1, Zul. Abweichung +- 0.3 | B6: Bauhöhe | C6: Bautiefe c Zul. Abweichung +- 2.0 | G6: Heizfläche je Glied in m2 für Bautiefe c | K6: Heizleistung von Heizkörpern bei tv = 90 °C, tr = 70 °C und ti = 20 °C | N6: Heizleistung von Heizkörpern bei tm = 80 °C, traum = 20 °C | S6: EN 442 ФL ΔT 50K 75/65/20°C | Z6: Nabenabstand h1, Zul. Abweichung +- 0.3 | AA6: Bauhöhe | AB6: Bautiefe c Zul. Abweichung +- 2.0 | AG6: Heizfläche je Glied in m2 für Bautiefe c | AL6: Heizleistung von Heizkörpern bei tv = 90 °C, tr = 70 °C und ti = 20 °C | AO6: Heizleistung von Heizkörpern bei tm = 80 °C, traum = 20 °C | AT6: Heizleistung von Heizkörpern bei tm = 100 °C, traum = 20 °C
G7: 110 | H7: 160 | I7: 220 | J7: 250 | K7: 110 | L7: 160 | M7: 220 | N7: 70 | O7: 110 | P7: 160 | Q7: 220 | R7: 250 | S7: 110 | T7: 160 | U7: 220 | AG7: 70 | AH7: 110 | AI7: 160 | AJ7: 220 | AK7: 250 | AL7: 110 | AM7: 160 | AN7: 220 | AO7: 70 | AP7: 110 | AQ7: 160 | AR7: 220 | AS7: 250 | AT7: 70 | AU7: 110 | AV7: 160 | AW7: 220 | AX7: 250
A8: 200 | B8: 300 | F8: 250 | J8: 0.16 | R8: 77 | Z8: 200 | AA8: 280 | AF8: 250 | AK8: 0.185 | AS8: 92 | AX8: 134
A9: 350 | B9: 450 | D9: 160 | E9: 220 | H9: 0.0155 | I9: 0.21 | P9: 74 | Q9: 99 | Z9: 350 | AA9: 430 | AD9: 160 | AE9: 220 | AI9: 0.185 | AJ9: 0.255 | AQ9: 93 | AR9: 122 | AV9: 135 | AW9: 177
A10: 500 | B10: 600 | C10: 110 | D10: 160 | E10: 220 | G10: 0.14 | H10: 0.205 | I10: 0.285 | K10: 73 | L10: 99 | M10: 130 | O10: 73 | P10: 99 | Q10: 128 | S10: =O10*('Basis Radiator'!$E$62/'Basis Radiator'!$F$62)^1.3 -> 58.048196 | T10: =P10*('Basis Radiator'!$E$62/'Basis Radiator'!$F$62)^1.3 -> 78.722896 | U10: =Q10*('Basis Radiator'!$E$62/'Basis Radiator'!$F$62)^1.3 -> 101.78314 | Z10: 500 | AA10: 580 | AC10: 110 | AD10: 160 | AE10: 220 | AH10: 0.18 | AI10: 0.255 | AJ10: 0.345 | AL10: 94 | AM10: 128 | AN10: 167 | AO10: 68 | AP10: 92 | AQ10: 126 | AR10: 162 | AT10: 99 | AU10: 134 | AV10: 183 | AW10: 235
A11: 900 | B11: 1000 | C11: 110 | D11: 160 | E11: 220 | G11: 0.24 | H11: 0.345 | I11: 0.48 | O11: 122 | P11: 157 | Q11: 204 | Z11: 900 | AA11: 980 | AB11: 70 | AD11: 160 | AE11: 220 | AG11: 0.205 | AI11: 0.44 | AJ11: 0.48 | AO11: 111 | AQ11: 204 | AR11: 260 | AT11: 161 | AV11: 297 | AW11: 378
G15: 105 | H15: 145 | I15: 185 | J15: 225 | S15: 105 | T15: 145 | U15: 185 | V15: 225
A16: Arbonia | B16: 500 | G16: ='Arbonia Tabelle'!J28 -> 0.12 | H16: ='Arbonia Tabelle'!J29 -> 0.17 | I16: ='Arbonia Tabelle'!J30 -> 0.21 | J16: ='Arbonia Tabelle'!J31 -> 0.25 | S16: ='Arbonia Tabelle'!J4 -> 53 | T16: ='Arbonia Tabelle'!J5 -> 69 | U16: ='Arbonia Tabelle'!J6 -> 85 | V16: ='Arbonia Tabelle'!J7 -> 99
G17: 100 | H17: 136 | I17: 173 | J17: 210 | S17: 100 | T17: 136 | U17: 173 | V17: 210
A18: Zehnder | B18: 500 | G18: ='Zehnder Charl. Tabelle'!H32 -> 0.11 | H18: ='Zehnder Charl. Tabelle'!H33 -> 0.15 | I18: ='Zehnder Charl. Tabelle'!H34 -> 0.19 | J18: ='Zehnder Charl. Tabelle'!H35 -> 0.23 | S18: ='Zehnder Charl. Tabelle'!H5 -> 51.6 | T18: ='Zehnder Charl. Tabelle'!H6 -> 67.6 | U18: ='Zehnder Charl. Tabelle'!H7 -> 83.5 | V18: ='Zehnder Charl. Tabelle'!H8 -> 99

Sheet Eigenschaften alle
A1: Typen | B1: Arbonia (Prolux, Kermi, etc.) | C1: Zehnder | D1: IRSAP (IT) | E1: Cordivari (IT) | F1: Fir Iron (IT) | G1: DIN 4722 Stahlradiatoren | H1: DIN 4722 Gussradiatoren | I1: Mittelwert | M1: Glieder (mm) | O1: Bauhöhe | P1: Arbonia (Prolux, Kermi, etc.) | Q1: Zehnder | R1: IRSAP | T1: DIN 4722 Stahlradiatoren | U1: DIN 4722 Gussradiatoren | W1: Baulange | X1: Arbonia (Prolux, Kermi, etc.) | Y1: Zehnder Charleston | Z1: Zehnder Charleston clinic
A2: 2 | B2: 65 | C2: 62 | D2: 65 | E2: 66 | F2: 63 | H2: 70 | I2: =AVERAGE(B2:F2) -> 64.2 | J2: bis 70 mm | L2: Arbonia (Prolux, Kermi, etc.) | M2: 45 | P2: 180 | Q2: 260 | R2: 200 | T2: 300 | U2: 280 | X2: 45 mm pro Glieder | Y2: 46 mm pro Glieder | Z2: 65 mm pro Glieder
A3: 3 | B3: 105 | C3: 100 | D3: 101 | E3: 107 | F3: 101 | G3: 110 | H3: 110 | I3: =AVERAGE(B3:F3) -> 102.8 | J3: bis 110 mm | L3: Zehnder | M3: 46 | P3: 190 | Q3: 292 | R3: 300 | T3: 450 | U3: 430 | W3: 2 | Z3: =65*W3+7 -> 137
A4: 4 | B4: 145 | C4: 136 | D4: 139 | E4: 148 | F4: 139 | G4: 160 | H4: 160 | I4: =AVERAGE(B4:F4) -> 141.4 | J4: bis 150 mm | L4: IRSAP (IT) | M4: 45 | P4: 260 | Q4: 300 | R4: 350 | T4: 600 | U4: 580 | W4: 4 | Y4: =W4*46+26 -> 210 | Z4: =65*W4+7 -> 267
A5: 5 | B5: 185 | C5: 173 | D5: 177 | E5: 189 | F5: 177 | G5: 220 | H5: 220 | I5: =AVERAGE(B5:F5) -> 180.2 | J5: bis 200 mm | L5: Cordivari (IT) | M5: 46 | P5: 300 | Q5: 342 | R5: 365 | T5: 1000 | U5: 980 | W5: 6 | X5: =W5*45 -> 270 | Y5: =W5*46+26 -> 302 | Z5: =65*W5+7 -> 397
A6: 6 | B6: 225 | C6: 210 | D6: 215 | E6: 230 | F6: 215 | G6: 250 | H6: 250 | I6: =AVERAGE(B6:F6) -> 219 | J6: bis 250 mm | L6: Fir Iron (IT) | M6: 50 | P6: 350 | Q6: 350 | R6: 400 | W6: 22 | X6: =W6*45 -> 990 | Y6: =W6*46+26 -> 1038 | Z6: =65*W6+7 -> 1437
L7: DIN 4722 Stahlradiatoren | M7: 50 | P7: 400 | Q7: 392 | R7: 450 | W7: 30 | X7: =W7*45 -> 1350 | Y7: =W7*46+26 -> 1406 | Z7: =65*W7+7 -> 1957
L8: DIN 4722 Gussradiatoren | M8: 60 | P8: 450 | Q8: 400 | R8: 500 | W8: 44 | X8: =W8*45 -> 1980 | Y8: =W8*46+26 -> 2050 | Z8: =65*W8+7 -> 2867
P9: 500 | Q9: 442 | R9: 535 | W9: 54 | X9: =W9*45 -> 2430 | Y9: =W9*46+26 -> 2510
P10: 550 | Q10: 450 | R10: 550 | W10: 59 | X10: =W10*45 -> 2655 | Y10: =W10*46+26 -> 2740
P11: 600 | Q11: 492 | R11: 565 | W11: 64 | X11: =W11*45 -> 2880 | Y11: =W11*46+26 -> 2970
P12: 750 | Q12: 500 | R12: 600 | W12: 66 | X12: =W12*45 -> 2970
P13: 900 | Q13: 542 | R13: 650
P14: 1000 | Q14: 550 | R14: 665
P15: 1100 | Q15: 592 | R15: 685
P16: 1200 | Q16: 600 | R16: 750
P17: 1500 | Q17: 742 | R17: 765
P18: 1800 | Q18: 750 | R18: 815
P19: 2000 | Q19: 892 | R19: 865
P20: 2200 | Q20: 900 | R20: 885
P21: 2500 | Q21: 992 | R21: 900
P22: 2800 | Q22: 1000 | R22: 1000
P23: 3000 | Q23: 1092 | R23: 1200
Q24: 1100 | R24: 1500
Q25: 1192 | R25: 1800
Q26: 1200 | R26: 2000
Q27: 1492 | R27: 2200
Q28: 1500 | R28: 2500
Q29: 1792
Q30: 1800
Q31: 1992
Q32: 2000
Q33: 2192
Q34: 2200
Q35: 2492
Q36: 2500
Q37: 2792
Q38: 2800
Q39: 2992
Q40: 3000

Sheet Leistung alle
A1: Heizleistung
B23: Arbonia | C23: Zehnder | D23: IRSAP | E23: Cordivari | F23: FIR Iron | G23: Mittelwert
A24: 2-Säule | B24: y = 0.0704x + 3.1521 | C24: y = 0.066x + 5.1012 | D24: y = 0.069x + 1.5026 | E24: y = 0.0739x + 2.2582 | F24: y = 0.0727x + 2.9525 | G24: y = 0.0701x + 3.1231 | I24: Cordivari | J24: FIR | K24: Arbonia | L24: IRSAP | M24: Zehnder | X24: Arbonia (Prolux, Kermi, etc.) | Y24: Zehnder | Z24: IRSAP (IT) | AA24: Cordivari (IT) | AB24: Fir Iron (IT)
I25: 66 | J25: 63 | K25: 65 | L25: 65 | M25: 62
A26: 3-Säule | B26: y = 0.0893x + 8.8262 | C26: y = 0.0874x + 7.5286 | D26: y = 0.0912x + 5.4758 | E26: y = 0.0959x + 7.5701 | F26: y = 0.0956x + 6.9839 | G26: y = 0.0911x + 7.6769 | I26: Cordivari | J26: FIR | K26: Arbonia | L26: IRSAP | M26: Zehnder | X26: 65 | Y26: 62 | Z26: 65 | AA26: 66 | AB26: 63
I27: 107 | J27: 101 | K27: 105 | L27: 101 | M27: 100
A28: 4-Säule | B28: y = 0.1127x + 12.391 | C28: y = 0.1116x + 11.375 | D28: y = 0.1145x + 9.7 | E28: y = 0.1191x + 12.684 | F28: y = 0.1186x + 11.012 | G28: y = 0.1145x + 11.758 | X28: 105 | Y28: 100 | Z28: 101 | AA28: 107 | AB28: 101
A30: 5-Säule | B30: y = 0.1288x + 22.511 | C30: y = 0.1351x + 15.436 | D30: y = 0.1383x + 12.141 | E30: y = 0.141x + 17.647 | F30: y = 0.1458x + 13.878 | G30: y = 0.137x + 16.647 | X30: 145 | Y30: 136 | Z30: 139 | AA30: 148 | AB30: 139
A32: 6-Säule | B32: y = 0.1578x + 17.294 | C32: y = 0.1575x + 19.8 | D32: y = 0.1621x + 14.609 | E32: y = 0.1544x + 31.894 | F32: y = 0.173x + 16.889 | G32: y = 0.1609x + 20.129 | X32: 185 | Y32: 173 | Z32: 177 | AA32: 189 | AB32: 177
X33: 225 | Y33: 210 | Z33: 215 | AA33: 230 | AB33: 215
A37: 2-Säule | B37: ='Zehnder Charl. Tabelle'!C$3 -> 260 | C37: ='Zehnder Charl. Tabelle'!D$3 -> 300 | D37: ='Zehnder Charl. Tabelle'!E$3 -> 350 | E37: ='Zehnder Charl. Tabelle'!F$3 -> 400 | F37: ='Zehnder Charl. Tabelle'!G$3 -> 450 | G37: ='Zehnder Charl. Tabelle'!H$3 -> 500 | H37: ='Zehnder Charl. Tabelle'!I$3 -> 550 | I37: ='Zehnder Charl. Tabelle'!J$3 -> 600 | ... U37: ='Zehnder Charl. Tabelle'!V$3 -> 3000
A38: Arbonia | B38: ='Arbonia Tabelle'!E3 -> 20 | C38: ='Arbonia Tabelle'!F3 -> 24 | D38: ='Arbonia Tabelle'!G3 -> 28 | E38: ='Arbonia Tabelle'!H3 -> 31 | F38: ='Arbonia Tabelle'!I3 -> 35 | G38: ='Arbonia Tabelle'!J3 -> 39 | H38: ='Arbonia Tabelle'!K3 -> 42 | I38: ='Arbonia Tabelle'!L3 -> 46 | ... U38: ='Arbonia Tabelle'!X3 -> 214
A39: Arbonia Formel | B39: =0.0704*B37 + 3.1521 -> 21.4561 | C39: =0.0704*C37 + 3.1521 -> 24.2721 | D39: =0.0704*D37 + 3.1521 -> 27.7921 | E39: =0.0704*E37 + 3.1521 -> 31.3121 | F39: =0.0704*F37 + 3.1521 -> 34.8321 | G39: =0.0704*G37 + 3.1521 -> 38.3521 | H39: =0.0704*H37 + 3.1521 -> 41.8721 | I39: =0.0704*I37 + 3.1521 -> 45.3921 | ... U39: =0.0704*U37 + 3.1521 -> 214.3521
A40: Zehnder | B40: ='Zehnder Charl. Tabelle'!C4 -> 21.1 | C40: ='Zehnder Charl. Tabelle'!D4 -> 23.6 | D40: ='Zehnder Charl. Tabelle'!E4 -> 27.5 | E40: ='Zehnder Charl. Tabelle'!F4 -> 31.2 | F40: ='Zehnder Charl. Tabelle'!G4 -> 34.9 | G40: ='Zehnder Charl. Tabelle'!H4 -> 38.4 | H40: ='Zehnder Charl. Tabelle'!I4 -> 41.9 | I40: ='Zehnder Charl. Tabelle'!J4 -> 45.3 | ... U40: ='Zehnder Charl. Tabelle'!V4 -> 201
A41: Zehnder Formel | B41: =0.066*B37 + 5.1012 -> 22.2612 | C41: =0.066*C37 + 5.1012 -> 24.9012 | D41: =0.066*D37 + 5.1012 -> 28.2012 | E41: =0.066*E37 + 5.1012 -> 31.5012 | F41: =0.066*F37 + 5.1012 -> 34.8012 | G41: =0.066*G37 + 5.1012 -> 38.1012 | H41: =0.066*H37 + 5.1012 -> 41.4012 | I41: =0.066*I37 + 5.1012 -> 44.7012 | ... U41: =0.066*U37 + 5.1012 -> 203.1012
A42: IRSAP | C42: ='IRSAP Tabelle'!D3 -> 23.4 | D42: ='IRSAP Tabelle'!E3 -> 26.8 | E42: ='IRSAP Tabelle'!G3 -> 30.1 | F42: ='IRSAP Tabelle'!H3 -> 33.4 | G42: ='IRSAP Tabelle'!I3 -> 36.7 | H42: ='IRSAP Tabelle'!K3 -> 39.9 | I42: ='IRSAP Tabelle'!M3 -> 43.2 | J42: ='IRSAP Tabelle'!Q3 -> 52.9 | K42: ='IRSAP Tabelle'!V3 -> 62.7 | L42: ='IRSAP Tabelle'!W3 -> 69.2 | N42: ='IRSAP Tabelle'!X3 -> 82.5 | O42: ='IRSAP Tabelle'!Y3 -> 103 | P42: ='IRSAP Tabelle'!Z3 -> 124.3 | Q42: ='IRSAP Tabelle'!AA3 -> 139 | R42: ='IRSAP Tabelle'!AB3 -> 154.2 | S42: ='IRSAP Tabelle'!AC3 -> 177.8
A43: IRSAP Formel | C43: =0.069*C37 + 1.5026 -> 22.2026 | D43: =0.069*D37 + 1.5026 -> 25.6526 | E43: =0.069*E37 + 1.5026 -> 29.1026 | F43: =0.069*F37 + 1.5026 -> 32.5526 | G43: =0.069*G37 + 1.5026 -> 36.0026 | H43: =0.069*H37 + 1.5026 -> 39.4526 | I43: =0.069*I37 + 1.5026 -> 42.9026 | J43: =0.069*J37 + 1.5026 -> 53.2526 | ... S43: =0.069*S37 + 1.5026 -> 174.0026
A44: Cordivari | C44: ='Cordivari Tabelle'!D3 -> 25.6 | E44: ='Cordivari Tabelle'!E3 -> 33 | G44: ='Cordivari Tabelle'!F3 -> 40.1 | H44: ='Cordivari Tabelle'!G3 -> 44 | I44: ='Cordivari Tabelle'!I3 -> 47.1 | J44: ='Cordivari Tabelle'!M3 -> 57.6 | L44: ='Cordivari Tabelle'!S3 -> 75.2 | N44: ='Cordivari Tabelle'!T3 -> 89.5 | O44: ='Cordivari Tabelle'!U3 -> 111.4 | P44: ='Cordivari Tabelle'!W3 -> 134.1 | Q44: ='Cordivari Tabelle'!Y3 -> 149.8 | R44: ='Cordivari Tabelle'!AA3 -> 165.9 | S44: ='Cordivari Tabelle'!AB3 -> 190.9
A45: Cordivari Formel | C45: =0.0739*C37 + 2.2582 -> 24.4282 | D45: =0.0739*D37 + 2.2582 -> 28.1232 | E45: =0.0739*E37 + 2.2582 -> 31.8182 | F45: =0.0739*F37 + 2.2582 -> 35.5132 | G45: =0.0739*G37 + 2.2582 -> 39.2082 | H45: =0.0739*H37 + 2.2582 -> 42.9032 | I45: =0.0739*I37 + 2.2582 -> 46.5982 | J45: =0.0739*J37 + 2.2582 -> 57.6832 | ... S45: =0.0739*S37 + 2.2582 -> 187.0082
A46: FIR Iron | C46: ='FIR Iron'!D3 -> 25.24 | D46: ='FIR Iron'!E3 -> 28.96 | E46: ='FIR Iron'!G3 -> 32.63 | F46: ='FIR Iron'!I3 -> 36.26 | G46: ='FIR Iron'!J3 -> 39.87 | H46: ='FIR Iron'!K3 -> 43.46 | I46: ='FIR Iron'!M3 -> 47.02 | J46: ='FIR Iron'!O3 -> 57.65 | K46: ='FIR Iron'!Q3 -> 68.22 | L46: ='FIR Iron'!S3 -> 75.26 | M46: ='FIR Iron'!U3 -> 83.2 | N46: ='FIR Iron'!V3 -> 89.35 | O46: ='FIR Iron'!W3 -> 110.64 | P46: ='FIR Iron'!X3 -> 132.23 | Q46: ='FIR Iron'!Y3 -> 146.83 | R46: ='FIR Iron'!Z3 -> 161.63 | S46: ='FIR Iron'!AA3 -> 184.23 | T46: ='FIR Iron'!AB3 -> 207.56 | U46: ='FIR Iron'!AC3 -> 223.1
A47: FIR Iron Formel | C47: =0.0727*C37 + 2.9525 -> 24.7625 | D47: =0.0727*D37 + 2.9525 -> 28.3975 | E47: =0.0727*E37 + 2.9525 -> 32.0325 | F47: =0.0727*F37 + 2.9525 -> 35.6675 | G47: =0.0727*G37 + 2.9525 -> 39.3025 | H47: =0.0727*H37 + 2.9525 -> 42.9375 | I47: =0.0727*I37 + 2.9525 -> 46.5725 | J47: =0.0727*J37 + 2.9525 -> 57.4775 | ... U47: =0.0727*U37 + 2.9525 -> 221.0525
A48: Mittelwert | B48: =AVERAGE(B38,B40,B42,B44,B46) -> 20.55 | C48: =AVERAGE(C38,C40,C42,C44,C46) -> 24.368 | D48: =AVERAGE(D38,D40,D42,D44,D46) -> 27.815 | E48: =AVERAGE(E38,E40,E42,E44,E46) -> 31.586 | F48: =AVERAGE(F38,F40,F42,F44,F46) -> 34.89 | G48: =AVERAGE(G38,G40,G42,G44,G46) -> 38.814 | H48: =AVERAGE(H38,H40,H42,H44,H46) -> 42.252 | I48: =AVERAGE(I38,I40,I42,I44,I46) -> 45.724 | ... U48: =AVERAGE(U38,U40,U42,U44,U46) -> 212.7
A49: Mittelwert Formel | B49: =0.0701*B37 + 3.1231 -> 21.3491 | C49: =0.0701*C37 + 3.1231 -> 24.1531 | D49: =0.0701*D37 + 3.1231 -> 27.6581 | E49: =0.0701*E37 + 3.1231 -> 31.1631 | F49: =0.0701*F37 + 3.1231 -> 34.6681 | G49: =0.0701*G37 + 3.1231 -> 38.1731 | H49: =0.0701*H37 + 3.1231 -> 41.6781 | I49: =0.0701*I37 + 3.1231 -> 45.1831 | ... U49: =0.0701*U37 + 3.1231 -> 213.4231
B50: =(B49-B48)/B48 -> 0.038885645 | C50: =(C49-C48)/C48 -> -0.0088189429 | D50: =(D49-D48)/D48 -> -0.0056408413 | E50: =(E49-E48)/E48 -> -0.013388843 | F50: =(F49-F48)/F48 -> -0.0063599885 | G50: =(G49-G48)/G48 -> -0.016512083 | H50: =(H49-H48)/H48 -> -0.013582789 | I50: =(I49-I48)/I48 -> -0.011829674 | ... U50: =(U49-U48)/U48 -> 0.0033996239
A52: max | B52: =MAX(B38,B40,B42,B44,B46) -> 21.1 | C52: =MAX(C38,C40,C42,C44,C46) -> 25.6 | D52: =MAX(D38,D40,D42,D44,D46) -> 28.96 | E52: =MAX(E38,E40,E42,E44,E46) -> 33 | F52: =MAX(F38,F40,F42,F44,F46) -> 36.26 | G52: =MAX(G38,G40,G42,G44,G46) -> 40.1 | H52: =MAX(H38,H40,H42,H44,H46) -> 44 | I52: =MAX(I38,I40,I42,I44,I46) -> 47.1 | ... U52: =MAX(U38,U40,U42,U44,U46) -> 223.1
A53: min | B53: =MIN(B38,B40,B42,B44,B46) -> 20 | C53: =MIN(C38,C40,C42,C44,C46) -> 23.4 | D53: =MIN(D38,D40,D42,D44,D46) -> 26.8 | E53: =MIN(E38,E40,E42,E44,E46) -> 30.1 | F53: =MIN(F38,F40,F42,F44,F46) -> 33.4 | G53: =MIN(G38,G40,G42,G44,G46) -> 36.7 | H53: =MIN(H38,H40,H42,H44,H46) -> 39.9 | I53: =MIN(I38,I40,I42,I44,I46) -> 43.2 | ... U53: =MIN(U38,U40,U42,U44,U46) -> 201
B54: =(B52-B53)/B52 -> 0.052132701 | C54: =(C52-C53)/C52 -> 0.0859375 | D54: =(D52-D53)/D52 -> 0.074585635 | E54: =(E52-E53)/E52 -> 0.087878788 | F54: =(F52-F53)/F52 -> 0.078874793 | G54: =(G52-G53)/G52 -> 0.08478803 | H54: =(H52-H53)/H52 -> 0.093181818 | I54: =(I52-I53)/I52 -> 0.082802548 | ... U54: =(U52-U53)/U52 -> 0.099058718
A55: 0.1
A57: 3-Säule | B57: ='Zehnder Charl. Tabelle'!C$3 -> 260 | C57: ='Zehnder Charl. Tabelle'!D$3 -> 300 | D57: ='Zehnder Charl. Tabelle'!E$3 -> 350 | E57: ='Zehnder Charl. Tabelle'!F$3 -> 400 | F57: ='Zehnder Charl. Tabelle'!G$3 -> 450 | G57: ='Zehnder Charl. Tabelle'!H$3 -> 500 | H57: ='Zehnder Charl. Tabelle'!I$3 -> 550 | I57: ='Zehnder Charl. Tabelle'!J$3 -> 600 | ... U57: ='Zehnder Charl. Tabelle'!V$3 -> 3000
A58: Arbonia | B58: ='Arbonia Tabelle'!E4 -> 28 | C58: ='Arbonia Tabelle'!F4 -> 33 | D58: ='Arbonia Tabelle'!G4 -> 38 | E58: ='Arbonia Tabelle'!H4 -> 43 | F58: ='Arbonia Tabelle'!I4 -> 48 | G58: ='Arbonia Tabelle'!J4 -> 53 | H58: ='Arbonia Tabelle'!K4 -> 58 | I58: ='Arbonia Tabelle'!L4 -> 63 | ... U58: ='Arbonia Tabelle'!X4 -> 270
A59: Arbonia Formel | B59: =0.0893*B57 + 8.8262 -> 32.0442 | C59: =0.0893*C57 + 8.8262 -> 35.6162 | D59: =0.0893*D57 + 8.8262 -> 40.0812 | E59: =0.0893*E57 + 8.8262 -> 44.5462 | F59: =0.0893*F57 + 8.8262 -> 49.0112 | G59: =0.0893*G57 + 8.8262 -> 53.4762 | H59: =0.0893*H57 + 8.8262 -> 57.9412 | I59: =0.0893*I57 + 8.8262 -> 62.4062 | ... U59: =0.0893*U57 + 8.8262 -> 276.7262
A60: Zehnder | B60: ='Zehnder Charl. Tabelle'!C5 -> 27.9 | C60: ='Zehnder Charl. Tabelle'!D5 -> 32 | D60: ='Zehnder Charl. Tabelle'!E5 -> 37 | E60: ='Zehnder Charl. Tabelle'!F5 -> 41.9 | F60: ='Zehnder Charl. Tabelle'!G5 -> 46.8 | G60: ='Zehnder Charl. Tabelle'!H5 -> 51.6 | H60: ='Zehnder Charl. Tabelle'!I5 -> 56.3 | I60: ='Zehnder Charl. Tabelle'!J5 -> 60.9 | ... U60: ='Zehnder Charl. Tabelle'!V5 -> 269
A61: Zehnder Formel | B61: =0.0874*B57 + 7.5286 -> 30.2526 | C61: =0.0874*C57 + 7.5286 -> 33.7486 | D61: =0.0874*D57 + 7.5286 -> 38.1186 | E61: =0.0874*E57 + 7.5286 -> 42.4886 | F61: =0.0874*F57 + 7.5286 -> 46.8586 | G61: =0.0874*G57 + 7.5286 -> 51.2286 | H61: =0.0874*H57 + 7.5286 -> 55.5986 | I61: =0.0874*I57 + 7.5286 -> 59.9686 | ... U61: =0.0874*U57 + 7.5286 -> 269.7286
A62: IRSAP | C62: ='IRSAP Tabelle'!D4 -> 32.5 | D62: ='IRSAP Tabelle'!E4 -> 37.3 | E62: ='IRSAP Tabelle'!G4 -> 42 | F62: ='IRSAP Tabelle'!H4 -> 46.7 | G62: ='IRSAP Tabelle'!I4 -> 51.4 | H62: ='IRSAP Tabelle'!K4 -> 55.9 | I62: ='IRSAP Tabelle'!M4 -> 60.6 | J62: ='IRSAP Tabelle'!Q4 -> 74.4 | K62: ='IRSAP Tabelle'!V4 -> 87.8 | L62: ='IRSAP Tabelle'!W4 -> 96.8 | N62: ='IRSAP Tabelle'!X4 -> 114.8 | O62: ='IRSAP Tabelle'!Y4 -> 141.7 | P62: ='IRSAP Tabelle'!Z4 -> 168.9 | Q62: ='IRSAP Tabelle'!AA4 -> 187.2 | R62: ='IRSAP Tabelle'!AB4 -> 205.7 | S62: ='IRSAP Tabelle'!AC4 -> 233.7
A63: IRSAP Formel | C63: =0.0912*C57 + 5.4758 -> 32.8358 | D63: =0.0912*D57 + 5.4758 -> 37.3958 | E63: =0.0912*E57 + 5.4758 -> 41.9558 | F63: =0.0912*F57 + 5.4758 -> 46.5158 | G63: =0.0912*G57 + 5.4758 -> 51.0758 | H63: =0.0912*H57 + 5.4758 -> 55.6358 | I63: =0.0912*I57 + 5.4758 -> 60.1958 | J63: =0.0912*J57 + 5.4758 -> 73.8758 | ... S63: =0.0912*S57 + 5.4758 -> 233.4758
A64: Cordivari | C64: ='Cordivari Tabelle'!D4 -> 34.7 | E64: ='Cordivari Tabelle'!E4 -> 45.1 | G64: ='Cordivari Tabelle'!F4 -> 55.2 | H64: ='Cordivari Tabelle'!G4 -> 60.9 | I64: ='Cordivari Tabelle'!I4 -> 65.2 | J64: ='Cordivari Tabelle'!M4 -> 80 | L64: ='Cordivari Tabelle'!S4 -> 104.3 | N64: ='Cordivari Tabelle'!T4 -> 123.5 | O64: ='Cordivari Tabelle'!U4 -> 151.9 | P64: ='Cordivari Tabelle'!W4 -> 180.2 | Q64: ='Cordivari Tabelle'!Y4 -> 199 | R64: ='Cordivari Tabelle'!AA4 -> 217.8 | S64: ='Cordivari Tabelle'!AB4 -> 245.9
A65: Cordivari Formel | C65: =0.0959*C57 + 7.5701 -> 36.3401 | D65: =0.0959*D57 + 7.5701 -> 41.1351 | E65: =0.0959*E57 + 7.5701 -> 45.9301 | F65: =0.0959*F57 + 7.5701 -> 50.7251 | G65: =0.0959*G57 + 7.5701 -> 55.5201 | H65: =0.0959*H57 + 7.5701 -> 60.3151 | I65: =0.0959*I57 + 7.5701 -> 65.1101 | J65: =0.0959*J57 + 7.5701 -> 79.4951 | ... S65: =0.0959*S57 + 7.5701 -> 247.3201
A66: FIR Iron | C66: ='FIR Iron'!D4 -> 35.4 | D66: ='FIR Iron'!E4 -> 40.5 | E66: ='FIR Iron'!G4 -> 45.52 | F66: ='FIR Iron'!I4 -> 50.47 | G66: ='FIR Iron'!J4 -> 55.38 | H66: ='FIR Iron'!K4 -> 60.25 | I66: ='FIR Iron'!M4 -> 65.07 | J66: ='FIR Iron'!O4 -> 79.4 | K66: ='FIR Iron'!Q4 -> 93.57 | L66: ='FIR Iron'!S4 -> 102.97 | M66: ='FIR Iron'!U4 -> 112.34 | N66: ='FIR Iron'!V4 -> 121.7 | O66: ='FIR Iron'!W4 -> 149.8 | P66: ='FIR Iron'!X4 -> 178.08 | Q66: ='FIR Iron'!Y4 -> 197.1 | R66: ='FIR Iron'!Z4 -> 216.28 | S66: ='FIR Iron'!AA4 -> 245.44 | T66: ='FIR Iron'!AB4 -> 275.09 | U66: ='FIR Iron'!AC4 -> 295.18
A67: FIR Iron Formel | C67: =0.0956*C57 + 6.9839 -> 35.6639 | D67: =0.0956*D57 + 6.9839 -> 40.4439 | E67: =0.0956*E57 + 6.9839 -> 45.2239 | F67: =0.0956*F57 + 6.9839 -> 50.0039 | G67: =0.0956*G57 + 6.9839 -> 54.7839 | H67: =0.0956*H57 + 6.9839 -> 59.5639 | I67: =0.0956*I57 + 6.9839 -> 64.3439 | J67: =0.0956*J57 + 6.9839 -> 78.6839 | ... U67: =0.0956*U57 + 6.9839 -> 293.7839
A68: Mittelwert | B68: =AVERAGE(B58,B60,B62,B64,B66) -> 27.95 | C68: =AVERAGE(C58,C60,C62,C64,C66) -> 33.52 | D68: =AVERAGE(D58,D60,D62,D64,D66) -> 38.2 | E68: =AVERAGE(E58,E60,E62,E64,E66) -> 43.504 | F68: =AVERAGE(F58,F60,F62,F64,F66) -> 47.9925 | G68: =AVERAGE(G58,G60,G62,G64,G66) -> 53.316 | H68: =AVERAGE(H58,H60,H62,H64,H66) -> 58.27 | I68: =AVERAGE(I58,I60,I62,I64,I66) -> 62.954 | ... U68: =AVERAGE(U58,U60,U62,U64,U66) -> 278.06
...

Sheet Emissionen alle
A1: THGE
B23: Arbonia | C23: Zehnder | E23: Cordivari | G23: Mittelwert
A24: 2-Säule | B24: y = 0.0016x + 0.0868 | C24: y = 0.0016x + 0.0148 | E24: y = 0.0017x + 0.0548 | G24: y = 0.0016x + 0.0569 | I24: Cordivari | K24: Arbonia | M24: Zehnder | X24: Arbonia (Prolux, Kermi, etc.) | Y24: Zehnder | Z24: IRSAP (IT) | AA24: Cordivari (IT) | AB24: Fir Iron (IT)
I25: 66 | K25: 65 | M25: 62
A26: 3-Säule | B26: y = 0.0023x + 0.1434 | C26: y = 0.0024x + 0.0206 | E26: y = 0.0025x + 0.0946 | G26: y = 0.0024x + 0.0988 | I26: Cordivari | K26: Arbonia | M26: Zehnder | X26: 65 | Y26: 62 | Z26: 65 | AA26: 66 | AB26: 63
I27: 107 | K27: 105 | M27: 100
A28: 4-Säule | B28: y = 0.0031x + 0.1839 | C28: y = 0.0032x + 0.0739 | E28: y = 0.0034x + 0.1412 | G28: y = 0.0032x + 0.1482 | X28: 105 | Y28: 100 | Z28: 101 | AA28: 107 | AB28: 101
A30: 5-Säule | B30: y = 0.0039x + 0.2803 | C30: y = 0.0041x + 0.0735 | E30: y = 0.0042x + 0.1701 | G30: y = 0.004x + 0.1919 | X30: 145 | Y30: 136 | Z30: 139 | AA30: 148 | AB30: 139
A32: 6-Säule | B32: y = 0.0047x + 0.3345 | C32: y = 0.0049x + 0.149 | E32: y = 0.005x + 0.2186 | G32: y = 0.0048x + 0.2597 | X32: 185 | Y32: 173 | Z32: 177 | AA32: 189 | AB32: 177
X33: 225 | Y33: 210 | Z33: 215 | AA33: 230 | AB33: 215
A37: 2-Säule | B37: ='Zehnder Charl. Tabelle'!C$3 -> 260 | C37: ='Zehnder Charl. Tabelle'!D$3 -> 300 | D37: ='Zehnder Charl. Tabelle'!E$3 -> 350 | E37: ='Zehnder Charl. Tabelle'!F$3 -> 400 | F37: ='Zehnder Charl. Tabelle'!G$3 -> 450 | G37: ='Zehnder Charl. Tabelle'!H$3 -> 500 | H37: ='Zehnder Charl. Tabelle'!I$3 -> 550 | I37: ='Zehnder Charl. Tabelle'!J$3 -> 600 | ... U37: ='Zehnder Charl. Tabelle'!V$3 -> 3000
A38: Arbonia | B38: ='Arbonia Tabelle'!E75 -> 0.478296 | C38: ='Arbonia Tabelle'!F75 -> 0.55772 | D38: ='Arbonia Tabelle'!G75 -> 0.644444 | E38: ='Arbonia Tabelle'!H75 -> 0.731168 | F38: ='Arbonia Tabelle'!I75 -> 0.774968 | G38: ='Arbonia Tabelle'!J75 -> 0.861692 | H38: ='Arbonia Tabelle'!K75 -> 0.948416 | I38: ='Arbonia Tabelle'!L75 -> 1.03514 | ... U38: ='Arbonia Tabelle'!X75 -> 4.797852
A39: Arbonia Formel | B39: =0.0016*B37 + 0.0868 -> 0.5028 | C39: =0.0016*C37 + 0.0868 -> 0.5668 | D39: =0.0016*D37 + 0.0868 -> 0.6468 | E39: =0.0016*E37 + 0.0868 -> 0.7268 | F39: =0.0016*F37 + 0.0868 -> 0.8068 | G39: =0.0016*G37 + 0.0868 -> 0.8868 | H39: =0.0016*H37 + 0.0868 -> 0.9668 | I39: =0.0016*I37 + 0.0868 -> 1.0468 | ... U39: =0.0016*U37 + 0.0868 -> 4.8868
A40: Zehnder | B40: ='Zehnder Charl. Tabelle'!C85 -> 0.463696 | C40: ='Zehnder Charl. Tabelle'!D85 -> 0.492896 | D40: ='Zehnder Charl. Tabelle'!E85 -> 0.58692 | E40: ='Zehnder Charl. Tabelle'!F85 -> 0.659044 | F40: ='Zehnder Charl. Tabelle'!G85 -> 0.753068 | G40: ='Zehnder Charl. Tabelle'!H85 -> 0.804168 | H40: ='Zehnder Charl. Tabelle'!I85 -> 0.890892 | I40: ='Zehnder Charl. Tabelle'!J85 -> 0.984916 | ... U40: ='Zehnder Charl. Tabelle'!V85 -> 4.915528
A41: Zehnder Formel | B41: =0.0016*B37 + 0.0148 -> 0.4308 | C41: =0.0016*C37 + 0.0148 -> 0.4948 | D41: =0.0016*D37 + 0.0148 -> 0.5748 | E41: =0.0016*E37 + 0.0148 -> 0.6548 | F41: =0.0016*F37 + 0.0148 -> 0.7348 | G41: =0.0016*G37 + 0.0148 -> 0.8148 | H41: =0.0016*H37 + 0.0148 -> 0.8948 | I41: =0.0016*I37 + 0.0148 -> 0.9748 | ... U41: =0.0016*U37 + 0.0148 -> 4.8148
A42: IRSAP
A43: IRSAP Formel
A44: Cordivari | C44: ='Cordivari Tabelle'!D75 -> 0.57232 | E44: ='Cordivari Tabelle'!E75 -> 0.717444 | G44: ='Cordivari Tabelle'!F75 -> 0.905492 | H44: ='Cordivari Tabelle'!G75 -> 1.006816 | I44: ='Cordivari Tabelle'!I75 -> 1.050616 | J44: ='Cordivari Tabelle'!M75 -> 1.332688 | L44: ='Cordivari Tabelle'!S75 -> 1.72426 | N44: ='Cordivari Tabelle'!T75 -> 2.057432 | O44: ='Cordivari Tabelle'!U75 -> 2.578652 | P44: ='Cordivari Tabelle'!W75 -> 3.099872 | Q44: ='Cordivari Tabelle'!Y75 -> 3.440344 | R44: ='Cordivari Tabelle'!AA75 -> 3.773516 | S44: ='Cordivari Tabelle'!AB75 -> 4.251812
A45: Cordivari Formel | C45: =0.0017*C37 + 0.0548 -> 0.5648 | D45: =0.0017*D37 + 0.0548 -> 0.6498 | E45: =0.0017*E37 + 0.0548 -> 0.7348 | F45: =0.0017*F37 + 0.0548 -> 0.8198 | G45: =0.0017*G37 + 0.0548 -> 0.9048 | H45: =0.0017*H37 + 0.0548 -> 0.9898 | I45: =0.0017*I37 + 0.0548 -> 1.0748 | J45: =0.0017*J37 + 0.0548 -> 1.3298 | ... S45: =0.0017*S37 + 0.0548 -> 4.3048
A46: FIR Iron
A47: FIR Iron Formel
A48: Mittelwert | B48: =AVERAGE(B38,B40,B42,B44,B46) -> 0.470996 | C48: =AVERAGE(C38,C40,C42,C44,C46) -> 0.54097867 | D48: =AVERAGE(D38,D40,D42,D44,D46) -> 0.615682 | E48: =AVERAGE(E38,E40,E42,E44,E46) -> 0.702552 | F48: =AVERAGE(F38,F40,F42,F44,F46) -> 0.764018 | G48: =AVERAGE(G38,G40,G42,G44,G46) -> 0.85711733 | H48: =AVERAGE(H38,H40,H42,H44,H46) -> 0.948708 | I48: =AVERAGE(I38,I40,I42,I44,I46) -> 1.0235573 | ... U48: =AVERAGE(U38,U40,U42,U44,U46) -> 4.85669
A49: Mittelwert Formel | B49: =0.0016*B37 + 0.0569 -> 0.4729 | C49: =0.0016*C37 + 0.0569 -> 0.5369 | D49: =0.0016*D37 + 0.0569 -> 0.6169 | E49: =0.0016*E37 + 0.0569 -> 0.6969 | F49: =0.0016*F37 + 0.0569 -> 0.7769 | G49: =0.0016*G37 + 0.0569 -> 0.8569 | H49: =0.0016*H37 + 0.0569 -> 0.9369 | I49: =0.0016*I37 + 0.0569 -> 1.0169 | ... U49: =0.0016*U37 + 0.0569 -> 4.8569
B50: =(B49-B48)/B48 -> 0.0040424972 | C50: =(C49-C48)/C48 -> -0.0075394224 | D50: =(D49-D48)/D48 -> 0.001978294 | E50: =(E49-E48)/E48 -> -0.0080449561 | F50: =(F49-F48)/F48 -> 0.016860859 | G50: =(G49-G48)/G48 -> -0.00025356311 | H50: =(H49-H48)/H48 -> -0.012446401 | I50: =(I49-I48)/I48 -> -0.0065041138 | ... U50: =(U49-U48)/U48 -> 4.3239326e-05
A52: max | B52: =MAX(B38,B40,B42,B44,B46) -> 0.478296 | C52: =MAX(C38,C40,C42,C44,C46) -> 0.57232 | D52: =MAX(D38,D40,D42,D44,D46) -> 0.644444 | E52: =MAX(E38,E40,E42,E44,E46) -> 0.731168 | F52: =MAX(F38,F40,F42,F44,F46) -> 0.774968 | G52: =MAX(G38,G40,G42,G44,G46) -> 0.905492 | H52: =MAX(H38,H40,H42,H44,H46) -> 1.006816 | I52: =MAX(I38,I40,I42,I44,I46) -> 1.050616 | ... U52: =MAX(U38,U40,U42,U44,U46) -> 4.915528
A53: min | B53: =MIN(B38,B40,B42,B44,B46) -> 0.463696 | C53: =MIN(C38,C40,C42,C44,C46) -> 0.492896 | D53: =MIN(D38,D40,D42,D44,D46) -> 0.58692 | E53: =MIN(E38,E40,E42,E44,E46) -> 0.659044 | F53: =MIN(F38,F40,F42,F44,F46) -> 0.753068 | G53: =MIN(G38,G40,G42,G44,G46) -> 0.804168 | H53: =MIN(H38,H40,H42,H44,H46) -> 0.890892 | I53: =MIN(I38,I40,I42,I44,I46) -> 0.984916 | ... U53: =MIN(U38,U40,U42,U44,U46) -> 4.797852
B54: =(B52-B53)/B52 -> 0.030525031 | C54: =(C52-C53)/C52 -> 0.13877551 | D54: =(D52-D53)/D52 -> 0.089261441 | E54: =(E52-E53)/E52 -> 0.098642173 | F54: =(F52-F53)/F52 -> 0.028259231 | G54: =(G52-G53)/G52 -> 0.11189939 | H54: =(H52-H53)/H52 -> 0.11513921 | I54: =(I52-I53)/I52 -> 0.062534742 | ... U54: =(U52-U53)/U52 -> 0.023939646
A55: 0.1
A57: 3-Säule | B57: ='Zehnder Charl. Tabelle'!C$3 -> 260 | C57: ='Zehnder Charl. Tabelle'!D$3 -> 300 | D57: ='Zehnder Charl. Tabelle'!E$3 -> 350 | E57: ='Zehnder Charl. Tabelle'!F$3 -> 400 | F57: ='Zehnder Charl. Tabelle'!G$3 -> 450 | G57: ='Zehnder Charl. Tabelle'!H$3 -> 500 | H57: ='Zehnder Charl. Tabelle'!I$3 -> 550 | I57: ='Zehnder Charl. Tabelle'!J$3 -> 600 | ... U57: ='Zehnder Charl. Tabelle'!V$3 -> 3000
A58: Arbonia | B58: ='Arbonia Tabelle'!E76 -> 0.760368 | C58: ='Arbonia Tabelle'!F76 -> 0.854392 | D58: ='Arbonia Tabelle'!G76 -> 0.963016 | E58: ='Arbonia Tabelle'!H76 -> 1.07164 | F58: ='Arbonia Tabelle'!I76 -> 1.180264 | G58: ='Arbonia Tabelle'!J76 -> 1.288888 | H58: ='Arbonia Tabelle'!K76 -> 1.447736 | I58: ='Arbonia Tabelle'!L76 -> 1.55636 | ... U58: ='Arbonia Tabelle'!X76 -> 7.150204
A59: Arbonia Formel | B59: =0.0023*B57 + 0.1434 -> 0.7414 | C59: =0.0023*C57 + 0.1434 -> 0.8334 | D59: =0.0023*D57 + 0.1434 -> 0.9484 | E59: =0.0023*E57 + 0.1434 -> 1.0634 | F59: =0.0023*F57 + 0.1434 -> 1.1784 | G59: =0.0023*G57 + 0.1434 -> 1.2934 | H59: =0.0023*H57 + 0.1434 -> 1.4084 | I59: =0.0023*I57 + 0.1434 -> 1.5234 | ... U59: =0.0023*U57 + 0.1434 -> 7.0434
A60: Zehnder | B60: ='Zehnder Charl. Tabelle'!C86 -> 0.666344 | C60: ='Zehnder Charl. Tabelle'!D86 -> 0.760368 | D60: ='Zehnder Charl. Tabelle'!E86 -> 0.876292 | E60: ='Zehnder Charl. Tabelle'!F86 -> 0.992216 | F60: ='Zehnder Charl. Tabelle'!G86 -> 1.10814 | G60: ='Zehnder Charl. Tabelle'!H86 -> 1.224064 | H60: ='Zehnder Charl. Tabelle'!I86 -> 1.339988 | I60: ='Zehnder Charl. Tabelle'!J86 -> 1.498836 | ... U60: ='Zehnder Charl. Tabelle'!V86 -> 7.33358
A61: Zehnder Formel | B61: =0.0024*B57 + 0.0206 -> 0.6446 | C61: =0.0024*C57 + 0.0206 -> 0.7406 | D61: =0.0024*D57 + 0.0206 -> 0.8606 | E61: =0.0024*E57 + 0.0206 -> 0.9806 | F61: =0.0024*F57 + 0.0206 -> 1.1006 | G61: =0.0024*G57 + 0.0206 -> 1.2206 | H61: =0.0024*H57 + 0.0206 -> 1.3406 | I61: =0.0024*I57 + 0.0206 -> 1.4606 | ... U61: =0.0024*U57 + 0.0206 -> 7.2206
A62: IRSAP
A63: IRSAP Formel
A64: Cordivari | C64: ='Cordivari Tabelle'!D76 -> 0.840668 | E64: ='Cordivari Tabelle'!E76 -> 1.12274 | G64: ='Cordivari Tabelle'!F76 -> 1.361888 | H64: ='Cordivari Tabelle'!G76 -> 1.492412 | I64: ='Cordivari Tabelle'!I76 -> 1.601036 | J64: ='Cordivari Tabelle'!M76 -> 2.006332 | L64: ='Cordivari Tabelle'!S76 -> 2.607852 | N64: ='Cordivari Tabelle'!T76 -> 3.129072 | O64: ='Cordivari Tabelle'!U76 -> 3.89674 | P64: ='Cordivari Tabelle'!W76 -> 4.614184 | Q64: ='Cordivari Tabelle'!Y76 -> 5.135404 | R64: ='Cordivari Tabelle'!AA76 -> 5.621 | S64: ='Cordivari Tabelle'!AB76 -> 6.381368
A65: Cordivari Formel | C65: =0.0025*C57 + 0.0946 -> 0.8446 | D65: =0.0025*D57 + 0.0946 -> 0.9696 | E65: =0.0025*E57 + 0.0946 -> 1.0946 | F65: =0.0025*F57 + 0.0946 -> 1.2196 | G65: =0.0025*G57 + 0.0946 -> 1.3446 | H65: =0.0025*H57 + 0.0946 -> 1.4696 | I65: =0.0025*I57 + 0.0946 -> 1.5946 | J65: =0.0025*J57 + 0.0946 -> 1.9696 | ... S65: =0.0025*S57 + 0.0946 -> 6.3446
A66: FIR Iron
A67: FIR Iron Formel
A68: Mittelwert | B68: =AVERAGE(B58,B60,B62,B64,B66) -> 0.713356 | C68: =AVERAGE(C58,C60,C62,C64,C66) -> 0.818476 | D68: =AVERAGE(D58,D60,D62,D64,D66) -> 0.919654 | E68: =AVERAGE(E58,E60,E62,E64,E66) -> 1.0621987 | F68: =AVERAGE(F58,F60,F62,F64,F66) -> 1.144202 | G68: =AVERAGE(G58,G60,G62,G64,G66) -> 1.2916133 | H68: =AVERAGE(H58,H60,H62,H64,H66) -> 1.426712 | I68: =AVERAGE(I58,I60,I62,I64,I66) -> 1.5520773 | ... U68: =AVERAGE(U58,U60,U62,U64,U66) -> 7.241892
...

Sheet Exponent alle
A1: Exponent
B23: Arbonia | C23: Zehnder | D23: IRSAP | E23: Cordivari | F23: FIR Iron | G23: Mittelwert | J23: Formulas:
A24: 2-Säule | G24: y = -2E-8x^2+8E-05x + 1.2298 | J24: Φ = Φn x (ΔT/ ΔTn)n | X24: Arbonia (Prolux, Kermi, etc.) | Y24: Zehnder | Z24: IRSAP (IT) | AA24: Cordivari (IT) | AB24: Fir Iron (IT)
N25: 75 | O25: 90
A26: 3-Säule | G26: y = -1E-8x^2+6E-05x + 1.2636 | J26: ΔT = (tin–tut) / (ln ( (tin – trum) / (tut – trum) ) ) | N26: 65 | O26: 70 | W26: 2-Säulen | X26: 65 | Y26: 62 | Z26: 65 | AA26: 66 | AB26: 63
N27: 20 | O27: 20 | W27: 3-Säulen | X27: 105 | Y27: 100 | Z27: 101 | AA27: 107 | AB27: 101
A28: 4-Säule | G28: y = -2E-8x^2+8E-05x + 1.2608 | J28: ΔTn | K28: =(N25-N26)/(LN((N25-N27)/(N26-N27))) -> 49.832887 | N28: =(N25-N26)/(LN((N25-N27)/(N26-N27))) -> 49.832887 | O28: =(O25-O26)/(LN((O25-O27)/(O26-O27))) -> 59.440268 | W28: 4-Säulen | X28: 145 | Y28: 136 | Z28: 139 | AA28: 148 | AB28: 139
W29: 5-Säulen | X29: 185 | Y29: 173 | Z29: 177 | AA29: 189 | AB29: 177
A30: 5-Säule | G30: y = -2E-8x^2+7E-05x + 1.2826 | J30: THGE | W30: 6-Säulen | X30: 225 | Y30: 210 | Z30: 215 | AA30: 230 | AB30: 215
J31: Stahl (kg) | K31: 0.73
A32: 6-Säule | G32: y = -2E-8x^2+6E-05x + 1.2931 | J32: Pulverbeschichten, Stahl (m2) | K32: 4.38 | L32: 120 | M32: g/m2 (80 micras, 1.5 g/cm3)
A37: 2-Säule | B37: ='Zehnder Charl. Tabelle'!C$3 -> 260 | C37: ='Zehnder Charl. Tabelle'!D$3 -> 300 | D37: ='Zehnder Charl. Tabelle'!E$3 -> 350 | E37: ='Zehnder Charl. Tabelle'!F$3 -> 400 | F37: ='Zehnder Charl. Tabelle'!G$3 -> 450 | G37: ='Zehnder Charl. Tabelle'!H$3 -> 500 | H37: ='Zehnder Charl. Tabelle'!I$3 -> 550 | I37: ='Zehnder Charl. Tabelle'!J$3 -> 600 | ... U37: ='Zehnder Charl. Tabelle'!V$3 -> 3000
A38: Arbonia | B38: ='Arbonia Tabelle'!E11 -> 1.25 | C38: ='Arbonia Tabelle'!F11 -> 1.26 | D38: ='Arbonia Tabelle'!G11 -> 1.31 | E38: ='Arbonia Tabelle'!H11 -> 1.31 | F38: ='Arbonia Tabelle'!I11 -> 1.31 | G38: ='Arbonia Tabelle'!J11 -> 1.31 | H38: ='Arbonia Tabelle'!K11 -> 1.31 | I38: ='Arbonia Tabelle'!L11 -> 1.31 | ... U38: ='Arbonia Tabelle'!X11 -> 1.33
A39: Arbonia Formel
A40: Zehnder | B40: ='Zehnder Charl. Tabelle'!C13 -> 1.27 | C40: ='Zehnder Charl. Tabelle'!D13 -> 1.27 | D40: ='Zehnder Charl. Tabelle'!E13 -> 1.26 | E40: ='Zehnder Charl. Tabelle'!F13 -> 1.26 | F40: ='Zehnder Charl. Tabelle'!G13 -> 1.26 | G40: ='Zehnder Charl. Tabelle'!H13 -> 1.25 | H40: ='Zehnder Charl. Tabelle'!I13 -> 1.25 | I40: ='Zehnder Charl. Tabelle'!J13 -> 1.25 | ... U40: ='Zehnder Charl. Tabelle'!V13 -> 1.27
A41: Zehnder Formel
A42: IRSAP | C42: ='IRSAP Tabelle'!D11 -> 1.24 | D42: ='IRSAP Tabelle'!E11 -> 1.24 | E42: ='IRSAP Tabelle'!G11 -> 1.25 | F42: ='IRSAP Tabelle'!H11 -> 1.25 | G42: ='IRSAP Tabelle'!I11 -> 1.25 | H42: ='IRSAP Tabelle'!K11 -> 1.26 | I42: ='IRSAP Tabelle'!M11 -> 1.26 | J42: ='IRSAP Tabelle'!Q11 -> 1.27 | K42: ='IRSAP Tabelle'!V11 -> 1.29 | L42: ='IRSAP Tabelle'!W11 -> 1.29 | N42: ='IRSAP Tabelle'!X11 -> 1.31 | O42: ='IRSAP Tabelle'!Y11 -> 1.33 | P42: ='IRSAP Tabelle'!Z11 -> 1.33 | Q42: ='IRSAP Tabelle'!AA11 -> 1.32 | R42: ='IRSAP Tabelle'!AB11 -> 1.31 | S42: ='IRSAP Tabelle'!AC11 -> 1.29
A43: IRSAP Formel
A44: Cordivari | C44: ='Cordivari Tabelle'!D11 -> 1.247 | E44: ='Cordivari Tabelle'!E11 -> 1.261 | G44: ='Cordivari Tabelle'!F11 -> 1.275 | H44: ='Cordivari Tabelle'!G11 -> 1.283 | I44: ='Cordivari Tabelle'!I11 -> 1.289 | J44: ='Cordivari Tabelle'!M11 -> 1.31 | L44: ='Cordivari Tabelle'!S11 -> 1.335 | N44: ='Cordivari Tabelle'!T11 -> 1.343 | O44: ='Cordivari Tabelle'!U11 -> 1.355 | P44: ='Cordivari Tabelle'!W11 -> 1.355 | Q44: ='Cordivari Tabelle'!Y11 -> 1.355 | R44: ='Cordivari Tabelle'!AA11 -> 1.355 | S44: ='Cordivari Tabelle'!AB11 -> 1.355
A45: Cordivari Formel
A46: FIR Iron | C46: ='FIR Iron'!D11 -> 1.22 | D46: ='FIR Iron'!E11 -> 1.23 | E46: ='FIR Iron'!G11 -> 1.23 | F46: ='FIR Iron'!I11 -> 1.23 | G46: ='FIR Iron'!J11 -> 1.24 | H46: ='FIR Iron'!K11 -> 1.24 | I46: ='FIR Iron'!M11 -> 1.24 | J46: ='FIR Iron'!O11 -> 1.25 | K46: ='FIR Iron'!Q11 -> 1.26 | L46: ='FIR Iron'!S11 -> 1.27 | M46: ='FIR Iron'!U11 -> 1.28 | N46: ='FIR Iron'!V11 -> 1.28 | O46: ='FIR Iron'!W11 -> 1.3 | P46: ='FIR Iron'!X11 -> 1.32 | Q46: ='FIR Iron'!Y11 -> 1.33 | R46: ='FIR Iron'!Z11 -> 1.34 | S46: ='FIR Iron'!AA11 -> 1.34 | T46: ='FIR Iron'!AB11 -> 1.34 | U46: ='FIR Iron'!AC11 -> 1.3
A47: FIR Iron Formel
A48: Mittelwert | B48: =AVERAGE(B38,B40,B42,B44,B46) -> 1.26 | C48: =AVERAGE(C38,C40,C42,C44,C46) -> 1.2474 | D48: =AVERAGE(D38,D40,D42,D44,D46) -> 1.26 | E48: =AVERAGE(E38,E40,E42,E44,E46) -> 1.2622 | F48: =AVERAGE(F38,F40,F42,F44,F46) -> 1.2625 | G48: =AVERAGE(G38,G40,G42,G44,G46) -> 1.265 | H48: =AVERAGE(H38,H40,H42,H44,H46) -> 1.2686 | I48: =AVERAGE(I38,I40,I42,I44,I46) -> 1.2698 | ... U48: =AVERAGE(U38,U40,U42,U44,U46) -> 1.3
A49: Mittelwert Formel | B49: =-0.00000002*B37^2+0.00008*B37 + 1.2298 -> 1.249248 | C49: =-0.00000002*C37^2+0.00008*C37 + 1.2298 -> 1.252 | D49: =-0.00000002*D37^2+0.00008*D37 + 1.2298 -> 1.25535 | E49: =-0.00000002*E37^2+0.00008*E37 + 1.2298 -> 1.2586 | F49: =-0.00000002*F37^2+0.00008*F37 + 1.2298 -> 1.26175 | G49: =-0.00000002*G37^2+0.00008*G37 + 1.2298 -> 1.2648 | H49: =-0.00000002*H37^2+0.00008*H37 + 1.2298 -> 1.26775 | I49: =-0.00000002*I37^2+0.00008*I37 + 1.2298 -> 1.2706 | ... U49: =-0.00000002*U37^2+0.00008*U37 + 1.2298 -> 1.2898
B50: =(B49-B48)/B48 -> -0.0085333333 | C50: =(C49-C48)/C48 -> 0.0036876704 | D50: =(D49-D48)/D48 -> -0.0036904762 | E50: =(E49-E48)/E48 -> -0.0028521629 | F50: =(F49-F48)/F48 -> -0.00059405941 | G50: =(G49-G48)/G48 -> -0.00015810277 | H50: =(H49-H48)/H48 -> -0.00067002995 | I50: =(I49-I48)/I48 -> 0.00063002048 | ... U50: =(U49-U48)/U48 -> -0.0078461538
W51: Hersteller | X51: Modell
A52: max | B52: =MAX(B38,B40,B42,B44,B46) -> 1.27 | C52: =MAX(C38,C40,C42,C44,C46) -> 1.27 | D52: =MAX(D38,D40,D42,D44,D46) -> 1.31 | E52: =MAX(E38,E40,E42,E44,E46) -> 1.31 | F52: =MAX(F38,F40,F42,F44,F46) -> 1.31 | G52: =MAX(G38,G40,G42,G44,G46) -> 1.31 | H52: =MAX(H38,H40,H42,H44,H46) -> 1.31 | I52: =MAX(I38,I40,I42,I44,I46) -> 1.31 | ... U52: =MAX(U38,U40,U42,U44,U46) -> 1.33 | W52: =MAX(A52:U52) -> 1.355 | X52: =MAX(A49:U49) -> 1.3098 | Y52: =(X52-W52)/W52 -> -0.033357934
A53: min | B53: =MIN(B38,B40,B42,B44,B46) -> 1.25 | C53: =MIN(C38,C40,C42,C44,C46) -> 1.22 | D53: =MIN(D38,D40,D42,D44,D46) -> 1.23 | E53: =MIN(E38,E40,E42,E44,E46) -> 1.23 | F53: =MIN(F38,F40,F42,F44,F46) -> 1.23 | G53: =MIN(G38,G40,G42,G44,G46) -> 1.24 | H53: =MIN(H38,H40,H42,H44,H46) -> 1.24 | I53: =MIN(I38,I40,I42,I44,I46) -> 1.24 | ... U53: =MIN(U38,U40,U42,U44,U46) -> 1.27 | W53: =MIN(A53:U53) -> 1.21 | X53: =MIN(A49:U49) -> 1.249248 | Y53: =(X53-W53)/W53 -> 0.032436364
B54: =(B52-B53)/B52 -> 0.015748031 | C54: =(C52-C53)/C52 -> 0.039370079 | D54: =(D52-D53)/D52 -> 0.061068702 | E54: =(E52-E53)/E52 -> 0.061068702 | F54: =(F52-F53)/F52 -> 0.061068702 | G54: =(G52-G53)/G52 -> 0.053435115 | H54: =(H52-H53)/H52 -> 0.053435115 | I54: =(I52-I53)/I52 -> 0.053435115 | ... U54: =(U52-U53)/U52 -> 0.045112782
A55: 0.1
A57: 3-Säule | B57: ='Zehnder Charl. Tabelle'!C$3 -> 260 | C57: ='Zehnder Charl. Tabelle'!D$3 -> 300 | D57: ='Zehnder Charl. Tabelle'!E$3 -> 350 | E57: ='Zehnder Charl. Tabelle'!F$3 -> 400 | F57: ='Zehnder Charl. Tabelle'!G$3 -> 450 | G57: ='Zehnder Charl. Tabelle'!H$3 -> 500 | H57: ='Zehnder Charl. Tabelle'!I$3 -> 550 | I57: ='Zehnder Charl. Tabelle'!J$3 -> 600 | ... U57: ='Zehnder Charl. Tabelle'!V$3 -> 3000
A58: Arbonia | B58: ='Arbonia Tabelle'!E12 -> 1.31 | C58: ='Arbonia Tabelle'!F12 -> 1.33 | D58: ='Arbonia Tabelle'!G12 -> 1.36 | E58: ='Arbonia Tabelle'!H12 -> 1.36 | F58: ='Arbonia Tabelle'!I12 -> 1.36 | G58: ='Arbonia Tabelle'!J12 -> 1.36 | H58: ='Arbonia Tabelle'!K12 -> 1.36 | I58: ='Arbonia Tabelle'!L12 -> 1.36 | ... U58: ='Arbonia Tabelle'!X12 -> 1.33
A59: Arbonia Formel
A60: Zehnder | B60: ='Zehnder Charl. Tabelle'!C14 -> 1.28 | C60: ='Zehnder Charl. Tabelle'!D14 -> 1.28 | D60: ='Zehnder Charl. Tabelle'!E14 -> 1.28 | E60: ='Zehnder Charl. Tabelle'!F14 -> 1.28 | F60: ='Zehnder Charl. Tabelle'!G14 -> 1.27 | G60: ='Zehnder Charl. Tabelle'!H14 -> 1.27 | H60: ='Zehnder Charl. Tabelle'!I14 -> 1.27 | I60: ='Zehnder Charl. Tabelle'!J14 -> 1.27 | ... U60: ='Zehnder Charl. Tabelle'!V14 -> 1.33
A61: Zehnder Formel
A62: IRSAP | C62: ='IRSAP Tabelle'!D12 -> 1.25 | D62: ='IRSAP Tabelle'!E12 -> 1.25 | E62: ='IRSAP Tabelle'!G12 -> 1.26 | F62: ='IRSAP Tabelle'!H12 -> 1.26 | G62: ='IRSAP Tabelle'!I12 -> 1.27 | H62: ='IRSAP Tabelle'!K12 -> 1.28 | I62: ='IRSAP Tabelle'!M12 -> 1.28 | J62: ='IRSAP Tabelle'!Q12 -> 1.3 | K62: ='IRSAP Tabelle'!V12 -> 1.31 | L62: ='IRSAP Tabelle'!W12 -> 1.32 | N62: ='IRSAP Tabelle'!X12 -> 1.32 | O62: ='IRSAP Tabelle'!Y12 -> 1.33 | P62: ='IRSAP Tabelle'!Z12 -> 1.33 | Q62: ='IRSAP Tabelle'!AA12 -> 1.318 | R62: ='IRSAP Tabelle'!AB12 -> 1.31 | S62: ='IRSAP Tabelle'!AC12 -> 1.299
A63: IRSAP Formel
A64: Cordivari | C64: ='Cordivari Tabelle'!D12 -> 1.273 | E64: ='Cordivari Tabelle'!E12 -> 1.284 | G64: ='Cordivari Tabelle'!F12 -> 1.296 | H64: ='Cordivari Tabelle'!G12 -> 1.302 | I64: ='Cordivari Tabelle'!I12 -> 1.307 | J64: ='Cordivari Tabelle'!M12 -> 1.325 | L64: ='Cordivari Tabelle'!S12 -> 1.345 | N64: ='Cordivari Tabelle'!T12 -> 1.35 | O64: ='Cordivari Tabelle'!U12 -> 1.359 | P64: ='Cordivari Tabelle'!W12 -> 1.341 | Q64: ='Cordivari Tabelle'!Y12 -> 1.33 | R64: ='Cordivari Tabelle'!AA12 -> 1.318 | S64: ='Cordivari Tabelle'!AB12 -> 1.301
A65: Cordivari Formel
A66: FIR Iron | C66: ='FIR Iron'!D12 -> 1.23 | D66: ='FIR Iron'!E12 -> 1.23 | E66: ='FIR Iron'!G12 -> 1.24 | F66: ='FIR Iron'!I12 -> 1.24 | G66: ='FIR Iron'!J12 -> 1.25 | H66: ='FIR Iron'!K12 -> 1.26 | I66: ='FIR Iron'!M12 -> 1.26 | J66: ='FIR Iron'!O12 -> 1.28 | K66: ='FIR Iron'!Q12 -> 1.29 | L66: ='FIR Iron'!S12 -> 1.3 | M66: ='FIR Iron'!U12 -> 1.3 | N66: ='FIR Iron'!V12 -> 1.31 | O66: ='FIR Iron'!W12 -> 1.33 | P66: ='FIR Iron'!X12 -> 1.34 | Q66: ='FIR Iron'!Y12 -> 1.34 | R66: ='FIR Iron'!Z12 -> 1.34 | S66: ='FIR Iron'!AA12 -> 1.34 | T66: ='FIR Iron'!AB12 -> 1.33 | U66: ='FIR Iron'!AC12 -> 1.32
...

Sheet Buch_Krupp
A1: Gussradiatoren nach DIN 4720 (Jan. 1961) | L1: GUSSRADIATOREN | M1: Leistung (W) tv: 90 °C, tr: 70 °C, ti: 20 °C | O1: Bauhöhe | T1: STAHLRADIATOREN | U1: Leistung (W) tv: 90 °C, tr: 70 °C, ti: 20 °C | W1: Bauhöhe | AB1: Norm-Wärmeleistung je Glied von Stahlrohrradiatoresn in W bei Warmwasser mit tm: 80 °C und Ti: 20 °C. Rohrdurchmesser 25 mm und Gliedbaulänge 45 mm
M2: ti: 20 °C | O2: 28 | P2: 43 | Q2: 58 | R2: 90 | U2: ti: 20 °C | W2: 30 | X2: 45 | Y2: 60 | Z2: 100
A3: Abmessungen und Gewichte | M3: Bautiefe | N3: 7 | R3: 112 | U3: Bautiefe | V3: 11 | Y3: 73 | Z3: 122
A4: Nebenabstand | B4: Bauhöhe | C4: Bautiefe (mm), Heizfläche (m2) und Gewicht pro Glied (kg) | N4: 11 | Q4: 92 | V4: 16 | X4: 74 | Y4: 99 | Z4: 157
A5: mm | B5: mm | C5: mm | D5: m2 | E5: kg | F5: mm | G5: m2 | H5: kg | I5: mm | J5: m2 | K5: kg | N5: 16 | P5: 93 | Q5: 126 | R5: 205 | V5: 22 | X5: 99 | Y5: 128 | Z5: 204
A6: 200 | B6: 280 | I6: 250 | J6: 0.185 | K6: 4.7 | N6: 22 | P6: 123 | Q6: 163 | R6: 261 | V6: 25 | W6: 77
A7: 350 | B7: 430 | F7: 160 | G7: 0.185 | H7: 4.5 | I7: 220 | J7: 0.255 | K7: 5.3 | N7: 25 | O7: 92
A8: 500 | B8: 580 | C8: 110 | D8: 0.18 | E8: 4.1 | F8: 160 | G8: 0.255 | H8: 5.4 | I8: 220 | J8: 0.345 | K8: 7.1 | M8: Oberfläche (m2) | O8: Bauhöhe | U8: Oberfläche (m2) | W8: Bauhöhe
A9: 900 | B9: 980 | C9: 70 | D9: 0.205 | E9: 5.1 | F9: 160 | G9: 0.44 | H9: 9.6 | I9: 220 | J9: 0.58 | K9: 12.5 | O9: 28 | P9: 43 | Q9: 58 | R9: 90 | W9: 30 | X9: 45 | Y9: 60 | Z9: 100
M10: Bautiefe | N10: 7 | R10: 0.205 | U10: Bautiefe | V10: 11 | Y10: 0.14 | Z10: 0.24
N11: 11 | Q11: 0.18 | V11: 16 | X11: 0.155 | Y11: 0.205 | Z11: 0.345
A12: Baulänge pro Glied 60 mm | N12: 16 | P12: 0.185 | Q12: 0.255 | R12: 0.44 | V12: 22 | X12: 0.21 | Y12: 0.285 | Z12: 0.48
N13: 22 | P13: 0.255 | Q13: 0.345 | R13: 0.58 | V13: 25 | W13: 0.16
A14: Stahlradiatoren nach DIN 4720 (Jan. 1961) | N14: 25 | O14: 0.185
M15: Leistung (W) tv: 90 °C, tr: 70 °C, ti: 10 °C | O15: Bauhöhe | U15: Leistung (W) tv: 90 °C, tr: 70 °C, ti: 10 °C | W15: Bauhöhe
A16: Abmessungen und Gewichte | M16: ti: 10 °C | O16: 28 | P16: 43 | Q16: 58 | R16: 90 | U16: ti: 10 °C | W16: 30 | X16: 45 | Y16: 60 | Z16: 100
A17: Nebenabstand | B17: Bauhöhe | C17: Bautiefe (mm), Heizfläche (m2) und Gewicht pro Glied (kg) | M17: Bautiefe | N17: 7 | R17: 136 | U17: Bautiefe | V17: 11 | Y17: 89 | Z17: 149
A18: mm | B18: mm | C18: mm | D18: m2 | E18: kg | F18: mm | G18: m2 | H18: kg | I18: mm | J18: m2 | K18: kg | N18: 11 | Q18: 112 | V18: 16 | X18: 91 | Y18: 121 | Z18: 192
A19: 200 | B19: 300 | I19: 250 | J19: 0.16 | K19: 1.7 | N19: 16 | P19: 114 | Q19: 153 | R19: 250 | V19: 22 | X19: 121 | Y19: 156 | Z19: 248
A20: 350 | B20: 450 | F20: 160 | G20: 0.155 | H20: 1.55 | I20: 220 | J20: 0.21 | K20: 2.2 | N20: 22 | P20: 150 | Q20: 199 | R20: 318 | V20: 25 | W20: 94
A21: 500 | B21: 600 | C21: 110 | D21: 0.14 | E21: 1.43 | F21: 160 | G21: 0.205 | H21: 2.06 | I21: 220 | J21: 0.285 | K21: 2.88 | N21: 25 | O21: 112
A22: 900 | B22: 1000 | C22: 110 | D22: 0.24 | E22: 2.43 | F22: 160 | G22: 0.345 | H22: 3.48 | I22: 220 | J22: 0.48 | K22: 4.83 | M22: Leistung (W) tv: 90 °C, tr: 70 °C, ti: 15 °C | O22: Bauhöhe | U22: Leistung (W) tv: 90 °C, tr: 70 °C, ti: 15 °C | W22: Bauhöhe
M23: ti: 15 °C | O23: 28 | P23: 43 | Q23: 58 | R23: 90 | U23: ti: 15 °C | W23: 30 | X23: 45 | Y23: 60 | Z23: 100
M24: Bautiefe | N24: 7 | R24: 124 | U24: Bautiefe | V24: 11 | Y24: 81 | Z24: 136
A25: Baulänge pro Glied 50 mm | N25: 11 | Q25: 102 | V25: 16 | X25: 83 | Y25: 110 | Z25: 174
N26: 16 | P26: 103 | Q26: 139 | R26: 227 | V26: 22 | X26: 110 | Y26: 142 | Z26: 226
N27: 22 | P27: 137 | Q27: 181 | R27: 289 | V27: 25 | W27: 85
N28: 25 | O28: 102
M29: Leistung (W) tv: 90 °C, tr: 70 °C, ti: 24 °C | O29: Bauhöhe | U29: Leistung (W) tv: 90 °C, tr: 70 °C, ti: 24 °C | W29: Bauhöhe
M30: ti: 24 °C | O30: 28 | P30: 43 | Q30: 58 | R30: 90 | U30: ti: 24 °C | W30: 30 | X30: 45 | Y30: 60 | Z30: 100
M31: Bautiefe | N31: 7 | R31: 102 | U31: Bautiefe | V31: 11 | Y31: 67 | Z31: 111
N32: 11 | Q32: 84 | V32: 16 | X32: 68 | Y32: 90 | Z32: 143
N33: 16 | P33: 85 | Q33: 114 | R33: 186 | V33: 22 | X33: 90 | Y33: 116 | Z33: 185
N34: 22 | P34: 112 | Q34: 148 | R34: 237 | V34: 25 | W34: 70
N35: 25 | O35: 84
M36: Leistung (W) tv: 75 °C, tr: 65 °C, ti: 20 °C | O36: Bauhöhe | U36: Leistung (W) tv: 75 °C, tr: 65 °C, ti: 20 °C | W36: Bauhöhe
M37: ti: 20 °C | O37: 28 | P37: 43 | Q37: 58 | R37: 90 | U37: ti: 20 °C | W37: 30 | X37: 45 | Y37: 60 | Z37: 100
M38: Bautiefe | N38: 7 | R38: =R3*('Basis Radiator'!$E$62/'Basis Radiator'!$F$62)^1.3 -> 89.060246 | U38: Bautiefe | V38: 11 | Y38: =Y3*('Basis Radiator'!$E$62/'Basis Radiator'!$F$62)^1.3 -> 58.048196 | Z38: 112
N39: 11 | Q39: =Q4*('Basis Radiator'!$E$62/'Basis Radiator'!$F$62)^1.3 -> 73.156631 | V39: 16 | X39: =X4*('Basis Radiator'!$E$62/'Basis Radiator'!$F$62)^1.3 -> 58.843377 | Y39: =Y4*('Basis Radiator'!$E$62/'Basis Radiator'!$F$62)^1.3 -> 78.722896 | Z39: =Z4*('Basis Radiator'!$E$62/'Basis Radiator'!$F$62)^1.3 -> 124.84338
N40: 16 | P40: =P5*('Basis Radiator'!$E$62/'Basis Radiator'!$F$62)^1.3 -> 73.951812 | Q40: =Q5*('Basis Radiator'!$E$62/'Basis Radiator'!$F$62)^1.3 -> 100.19278 | R40: =R5*('Basis Radiator'!$E$62/'Basis Radiator'!$F$62)^1.3 -> 163.01206 | V40: 22 | X40: =X5*('Basis Radiator'!$E$62/'Basis Radiator'!$F$62)^1.3 -> 78.722896 | Y40: =Y5*('Basis Radiator'!$E$62/'Basis Radiator'!$F$62)^1.3 -> 101.78314 | Z40: =Z5*('Basis Radiator'!$E$62/'Basis Radiator'!$F$62)^1.3 -> 162.21688
...

Sheet Wärmetransfer_Krupp
A1: Strahlungsanteil | K1: https://www.heizsparer.de/heizung/heizkorper/die-wichtigsten-heizkoerper-typen-im-ueberblick | Q1: Seite 351. Bild 8.24 Wärmestrome (W/m) von wasserbeheizten, ungedämmten Stahlrohrleitungen an die Umgebung in Abhängigkeit von der Temperatur und den Nenndurchmesser
C2: [1] | D2: [2, 3] | F2: [1] | G2: VDI_Wärmeatlas. 4- Aufl. Düsseldorf: VDI-Verlag 1984 | L2: Heizfläche | M2: Anteil Strahlungswärme | N2: (Durchschnitt) | Q2: Waagerechtes Rohr | R2: Durchmesser | S2: Basis: W: 0.5 m/s; λR: 50 W/(mK); ε: 0.92 | AA2: Senrechtes Rohr | AB2: Durchmesser
A3: Gliederheizkörper | C3: 0.25 | D3: 0.21-0.36 | F3: [2] | G3: Kast & Klan. Energieeinsparungsmöglichkeiten in Zentralheizungsanlagen - Einfluss der Vorlauftemperatur des Heizsystems auf den Energieverbrauch und die Wärmeabgabe von Heizkörper. Forschungsbericht des Bundesministeriums dür Forschung und Technologie. 1984 | L3: Flächenheizung | M3: Fußbodenheizung | N3: 0.95 | P3: Atlog | R3: 17.2 | S3: 21.3 | T3: 26.9 | U3: 33.7 | V3: 42.4 | W3: 48.3 | X3: 60.3 | Z3: Atlog | AB3: 17.2 | AC3: 21.3 | AD3: 26.9 | AE3: 33.7 | AF3: 42.4 | AG3: 48.3 | AH3: 60.3
A4: Einreihige Plattenheizkörper ohne Konvektionsteil | C4: 0.4 | D4: 0.4-0.57 | F4: [3] | G4: Schlapmann. Wärmestrahlung von Raumheizkörper. Haustechnische Rundschau (1987) Heft 2 | M4: Wandheizung | N4: 0.9 | Q4: 10 | U4: 10.8 | V4: 13.25 | W4: 14.9 | X4: 17.3 | AA4: 10 | AE4: 11.8 | AF4: 13.25 | AG4: 14.9 | AH4: 17.3
A5: Einreihige Plattenheizkörper mit Konvektionsteil und zweireihige Plattenheizkörper ohne Konvektionsteil | C5: 0.25 | D5: 0.33-0.42 | F5: [4] | G5: Glück. Wärmeübertragung. Wärmeabgabe von Raumheizflächen und Rohren | L5: DIN Radiator | M5: Stahl | N5: 0.4 | Q5: 12 | T5: 10.9 | U5: 13.4 | V5: 16.8 | W5: 17 | X5: 22 | AA5: 12 | AE5: 11.6 | AF5: 14.7 | AG5: 16.8 | AH5: 19.5
A6: Zwei- und mehrreihige Plattenheizkörper mit Konvektionsteil | C6: 0.15 | D6: 0.18-0.30 | M6: Guss | N6: 0.35 | Q6: 14 | S6: 10.4 | T6: 12.8 | U6: 15.2 | V6: 20 | W6: 22.5 | X6: 26 | AA6: 14 | AD6: 10.8 | AE6: 13.8 | AF6: 17 | AG6: 20 | AH6: 23.5
A7: Konvektoren | C7: 0 | D7: 0.11 | L7: Röhrenradiator | M7: 2-Säuler | N7: 0.4 | Q7: 16 | R7: 10.4 | S7: 11.8 | T7: 15 | U7: 18.2 | V7: 22.5 | W7: 25 | X7: 30 | AA7: 16 | AC7: 10.1 | AD7: 12.8 | AE7: 16 | AF7: 20 | AG7: 22.8 | AH7: 27
A8: Füssbodenheizungen | D8: 0.55-.70 | M8: 4-Säuler | N8: 0.25 | Q8: 18 | R8: 11.8 | S8: 14.8 | T8: 17.5 | U8: 21.5 | V8: 26 | W8: 29 | X8: 34.5 | AA8: 18 | AC8: 12 | AD8: 14.8 | AE8: 18.5 | AF8: 23.4 | AG8: 26.5 | AH8: 31.5
M9: 6-Säuler | N9: 0.2 | Q9: 20 | R9: 13.2 | S9: 16 | T9: 19.5 | U9: 23.8 | V9: 29.5 | W9: 33 | X9: 39 | AA9: 20 | AB9: 10.9 | AC9: 13 | AD9: 16.8 | AE9: 20.9 | AF9: 26 | AG9: 29.5 | AH9: 35
A10: Plattenheizkörper: P (Plattengrundkörper), S (Sekundärheizfläche)) | C10: [4] | L10: Plattenheizkörper | M10: Typ 10 | N10: 0.55 | Q10: 25 | R10: 17.5 | S10: 21.2 | T10: 25.5 | U10: 31.4 | V10: 38.5 | W10: 42.5 | X10: 50.5 | AA10: 25 | AB10: 14 | AC10: 17.5 | AD10: 22 | AE10: 27 | AF10: 34 | AG10: 39 | AH10: 46
A11: PS | C11: 0.30-0.40 | M11: Typ 11 | N11: 0.35 | Q11: 30 | R11: 22 | S11: 26.2 | T11: 32 | U11: 39.5 | V11: 48 | W11: 53 | X11: 63.5 | AA11: 30 | AB11: 17.5 | AC11: 22 | AD11: 27 | AE11: 34 | AF11: 43 | AG11: 48 | AH11: 57
A12: PSSP | C12: 0.15-0.20 | M12: Typ 21 | N12: 0.3 | Q12: 35 | R12: 25.5 | S12: 31.4 | T12: 36 | U12: 48 | V12: 60 | W12: 63 | X12: 75 | AA12: 35 | AB12: 21 | AC12: 26 | AD12: 34 | AE12: 41 | AF12: 52 | AG12: 59.5 | AH12: 70
A13: PSPSSP | C13: 0.15 | M13: Typ 22 | N13: 0.25 | Q13: 40 | R13: 31 | S13: 37 | T13: 45 | U13: 56 | V13: 68 | W13: 77 | X13: 89 | AA13: 40 | AB13: 24.5 | AC13: 30.3 | AD13: 38.9 | AE13: 48.5 | AF13: 60 | AG13: 68.5 | AH13: 80
A14: SPSSPSSPS | C14: 0.05 | M14: Typ 33 | N14: 0.2 | Q14: 50 | R14: 41.5 | S14: 49.7 | T14: 59.5 | U14: 73 | V14: 90 | W14: 101 | X14: 120 | AA14: 50 | AB14: 32.5 | AC14: 40 | AD14: 50.5 | AE14: 62.5 | AF14: 79 | AG14: 90 | AH14: 109
L15: Konvektor | M15: mit Stahlblechverkleidung | N15: 0.05 | Q15: 60 | R15: 51 | S15: 61 | T15: 74.5 | U15: 91 | V15: 114 | W15: 128 | X15: 150 | AA15: 60 | AB15: 40 | AC15: 50 | AD15: 63.5 | AE15: 79 | AF15: 100 | AG15: 114 | AH15: 136
M16: Unterflurkonvektor | N16: <5 % | Q16: 70 | R16: 62.5 | S16: 75 | T16: 91 | U16: 112 | V16: 140 | W16: 157 | X16: 180 | AA16: 70 | AB16: 49.5 | AC16: 61 | AD16: 77 | AE16: 96 | AF16: 123 | AG16: 138 | AH16: 155
Q17: 80 | R17: 73 | S17: 99 | T17: 110 | U17: 130 | V17: 160 | W17: 180 | AA17: 80 | AB17: 59 | AC17: 74 | AD17: 93 | AE17: 113 | AF17: 145 | AG17: 160 | AH17: 195
A18: Heizflächenexponent (n) | D18: Diese Exponent kann maximal im èbertemperaturbereich von 30 K < Δtlog < 100 K | R18: =E4-5*Q18^3+0.0088*Q18^2+0.4698*Q18+0.7613 -> 0.7613
A19: Radiatoren | B19: 1.3
A20: Plattenheizkörper | B20: 1.25-1.38
A21: Konvektortruhen | B21: 1.30-1.40
A22: Rohre | B22: 1.25-1.26
A23: Strahlplatten | B23: 1.15-1.25
A24: Fussbodenheizung | B24: 1.00-1.15 | Q24: Zoll | R24: DN | S24: Aussendurchmesser [mm] | T24: Innendurchmesser [mm]
Q25: 3/8" | R25: DN 10 | S25: 17.2 | T25: 13.6
Q26: 1/2" | R26: DN 15 | S26: 21.3 | T26: 17.5
A27: Bei kurzen Heizkörpern (geringe Gliedzahlen) ist wegen der relativ günstigeren Abstrahlung die Leistung geringfügig höher als bei langen Heizkörper. | Q27: 3/4" | R27: DN 20 | S27: 26.9 | T27: 22.9
A28: Die Unterschied kann aber vernachlässigt werden, so dass man mit einer konstanten Gliederleistung rechnen kann | Q28: 1" | R28: DN 25 | S28: 33.7 | T28: 29.9
Q29: 1 1/4" | R29: DN 32 | S29: 42.4 | T29: 38
Q30: 1 1/2" | R30: DN 40 | S30: 48.3 | T30: 43.9
Q31: 2" | R31: DN 50 | S31: 60.3 | T31: 55.9
X47: =-0.00004 -> -4e-05
Q56: Waagerechtes Rohr | R56: Durchmesser | S56: Basis: W: 0.5 m/s; λR: 50 W/(mK); ε: 0.92 | AB56: Senrechtes Rohr | AC56: Durchmesser
R57: 17.2 | S57: 21.3 | T57: 26.9 | U57: 33.7 | V57: 42.4 | W57: 48.3 | X57: 60.3 | AC57: 17.2 | AD57: 21.3 | AE57: 26.9 | AF57: 33.7 | AG57: 42.4 | AH57: 48.3 | AI57: 60.3
Q58: 10 | U58: =0.005*Q58^2 + 1.2759*Q58 - 3.16 -> 10.099 | V58: =0.0064*Q58^2 + 1.5641*Q58 - 3.7326 -> 12.5484 | W58: =0.008*Q58^2 + 1.6994*Q58 - 4.0845 -> 13.7095 | X58: =0.0106*Q58^2 + 1.8917*Q58 - 2.8417 -> 17.1353 | AB58: 10 | AF58: =0.0053*AB58^2 + 1.0037*AB58 - 0.8355 -> 9.7315 | AG58: =0.0075*AB58^2 + 1.2373*AB58 - 1.2004 -> 11.9226 | AH58: =0.0066*AB58^2 + 1.5296*AB58 - 2.7819 -> 13.1741 | AI58: =0.0086*AB58^2 + 1.7426*AB58 - 2.4777 -> 15.8083
Q59: 12 | T59: =0.0064*Q59^2 + 0.8663*Q59 - 0.3996 -> 10.9176 | U59: =0.005*Q59^2 + 1.2759*Q59 - 3.16 -> 12.8708 | V59: =0.0064*Q59^2 + 1.5641*Q59 - 3.7326 -> 15.9582 | W59: =0.008*Q59^2 + 1.6994*Q59 - 4.0845 -> 17.4603 | X59: =0.0106*Q59^2 + 1.8917*Q59 - 2.8417 -> 21.3851 | AB59: 12 | AF59: =0.0053*AB59^2 + 1.0037*AB59 - 0.8355 -> 11.9721 | AG59: =0.0075*AB59^2 + 1.2373*AB59 - 1.2004 -> 14.7272 | AH59: =0.0066*AB59^2 + 1.5296*AB59 - 2.7819 -> 16.5237 | AI59: =0.0086*AB59^2 + 1.7426*AB59 - 2.4777 -> 19.6719
Q60: 14 | S60: =0.0082*Q60^2 + 0.5162*Q60 + 2.4882 -> 11.3222 | T60: =0.0064*Q60^2 + 0.8663*Q60 - 0.3996 -> 12.983 | U60: =0.005*Q60^2 + 1.2759*Q60 - 3.16 -> 15.6826 | V60: =0.0064*Q60^2 + 1.5641*Q60 - 3.7326 -> 19.4192 | W60: =0.008*Q60^2 + 1.6994*Q60 - 4.0845 -> 21.2751 | X60: =0.0106*Q60^2 + 1.8917*Q60 - 2.8417 -> 25.7197 | AB60: 14 | AE60: =0.0053*AB58^2 + 1.0037*AB58 - 0.8355 -> 9.7315 | AF60: =0.0053*AB60^2 + 1.0037*AB60 - 0.8355 -> 14.2551 | AG60: =0.0075*AB60^2 + 1.2373*AB60 - 1.2004 -> 17.5918 | AH60: =0.0066*AB60^2 + 1.5296*AB60 - 2.7819 -> 19.9261 | AI60: =0.0086*AB60^2 + 1.7426*AB60 - 2.4777 -> 23.6043
Q61: 16 | R61: =0.0028*Q61^2 + 0.7173*Q61 - 2.1502 -> 10.0434 | S61: =0.0077*Q61^2 + 0.5619*Q61 + 1.8479 -> 12.8095 | T61: =0.0064*Q61^2 + 0.8663*Q61 - 0.3996 -> 15.0996 | U61: =0.005*Q61^2 + 1.2759*Q61 - 3.16 -> 18.5344 | V61: =0.0064*Q61^2 + 1.5641*Q61 - 3.7326 -> 22.9314 | W61: =0.008*Q61^2 + 1.6994*Q61 - 4.0845 -> 25.1539 | X61: =0.0106*Q61^2 + 1.8917*Q61 - 2.8417 -> 30.1391 | AB61: 16 | AD61: 10.1 | AE61: =0.0053*AB59^2 + 1.0037*AB59 - 0.8355 -> 11.9721 | AF61: =0.0053*AB61^2 + 1.0037*AB61 - 0.8355 -> 16.5805 | AG61: =0.0075*AB61^2 + 1.2373*AB61 - 1.2004 -> 20.5164 | AH61: =0.0066*AB61^2 + 1.5296*AB61 - 2.7819 -> 23.3813 | AI61: =0.0086*AB61^2 + 1.7426*AB61 - 2.4777 -> 27.6055
Q62: 18 | R62: =0.0028*Q62^2 + 0.7173*Q62 - 2.1502 -> 11.6684 | S62: =0.0077*Q62^2 + 0.5619*Q62 + 1.8479 -> 14.4569 | T62: =0.0064*Q62^2 + 0.8663*Q62 - 0.3996 -> 17.2674 | U62: =0.005*Q62^2 + 1.2759*Q62 - 3.16 -> 21.4262 | V62: =0.0064*Q62^2 + 1.5641*Q62 - 3.7326 -> 26.4948 | W62: =0.008*Q62^2 + 1.6994*Q62 - 4.0845 -> 29.0967 | X62: =0.0106*Q62^2 + 1.8917*Q62 - 2.8417 -> 34.6433 | AB62: 18 | AD62: 12 | AE62: =0.0053*AB60^2 + 1.0037*AB60 - 0.8355 -> 14.2551 | AF62: =0.0053*AB62^2 + 1.0037*AB62 - 0.8355 -> 18.9483 | AG62: =0.0075*AB62^2 + 1.2373*AB62 - 1.2004 -> 23.501 | AH62: =0.0066*AB62^2 + 1.5296*AB62 - 2.7819 -> 26.8893 | AI62: =0.0086*AB62^2 + 1.7426*AB62 - 2.4777 -> 31.6755
Q63: 20 | R63: =0.0028*Q63^2 + 0.7173*Q63 - 2.1502 -> 13.3158 | S63: =0.0077*Q63^2 + 0.5619*Q63 + 1.8479 -> 16.1659 | T63: =0.0064*Q63^2 + 0.8663*Q63 - 0.3996 -> 19.4864 | U63: =0.005*Q63^2 + 1.2759*Q63 - 3.16 -> 24.358 | V63: =0.0064*Q63^2 + 1.5641*Q63 - 3.7326 -> 30.1094 | W63: =0.008*Q63^2 + 1.6994*Q63 - 4.0845 -> 33.1035 | X63: =0.0106*Q63^2 + 1.8917*Q63 - 2.8417 -> 39.2323 | AB63: 20 | AC63: 10.9 | AD63: 13 | AE63: =0.0053*AB61^2 + 1.0037*AB61 - 0.8355 -> 16.5805 | AF63: =0.0053*AB63^2 + 1.0037*AB63 - 0.8355 -> 21.3585 | AG63: =0.0075*AB63^2 + 1.2373*AB63 - 1.2004 -> 26.5456 | AH63: =0.0066*AB63^2 + 1.5296*AB63 - 2.7819 -> 30.4501 | AI63: =0.0086*AB63^2 + 1.7426*AB63 - 2.4777 -> 35.8143
...

Sheet Arbonia Tabelle
A1: Leistung (W) | C1: Bauhöhe
A2: 75/65/20 °C | C2: 180 | D2: 190 | E2: 260 | F2: 300 | G2: 350 | H2: 400 | I2: 450 | J2: 500 | K2: 550 | L2: 600 | M2: 750 | N2: 900 | O2: 1000 | P2: 1100 | Q2: 1200 | R2: 1500 | S2: 1800 | T2: 2000 | U2: 2200 | V2: 2500 | W2: 2800 | X2: 3000
A3: Bautiefe | B3: 65 | C3: {=_xlfn.XLOOKUP(1,('Arbonia Original'!$A$2:$A$117=C$2)*('Arbonia Original'!$B$2:$B$117=$B3),'Arbonia Original'!$D$2:$D$117,"")} | D3: {=_xlfn.XLOOKUP(1,('Arbonia Original'!$A$2:$A$117=D$2)*('Arbonia Original'!$B$2:$B$117=$B3),'Arbonia Original'!$D$2:$D$117,"")} -> 15 | E3: {=_xlfn.XLOOKUP(1,('Arbonia Original'!$A$2:$A$117=E$2)*('Arbonia Original'!$B$2:$B$117=$B3),'Arbonia Original'!$D$2:$D$117,"")} -> 20 | F3: {=_xlfn.XLOOKUP(1,('Arbonia Original'!$A$2:$A$117=F$2)*('Arbonia Original'!$B$2:$B$117=$B3),'Arbonia Original'!$D$2:$D$117,"")} -> 24 | G3: {=_xlfn.XLOOKUP(1,('Arbonia Original'!$A$2:$A$117=G$2)*('Arbonia Original'!$B$2:$B$117=$B3),'Arbonia Original'!$D$2:$D$117,"")} -> 28 | H3: {=_xlfn.XLOOKUP(1,('Arbonia Original'!$A$2:$A$117=H$2)*('Arbonia Original'!$B$2:$B$117=$B3),'Arbonia Original'!$D$2:$D$117,"")} -> 31 | I3: {=_xlfn.XLOOKUP(1,('Arbonia Original'!$A$2:$A$117=I$2)*('Arbonia Original'!$B$2:$B$117=$B3),'Arbonia Original'!$D$2:$D$117,"")} -> 35 | J3: {=_xlfn.XLOOKUP(1,('Arbonia Original'!$A$2:$A$117=J$2)*('Arbonia Original'!$B$2:$B$117=$B3),'Arbonia Original'!$D$2:$D$117,"")} -> 39 | ... X3: {=_xlfn.XLOOKUP(1,('Arbonia Original'!$A$2:$A$117=X$2)*('Arbonia Original'!$B$2:$B$117=$B3),'Arbonia Original'!$D$2:$D$117,"")} -> 214 | Y3: ARB 2-Säule
